Workbook
Name _1: 'Jan-2026'!$J$9
Name _2: 'Jan-2026'!$AU$9
Name _3: 'Jan-2026'!$CF$9
Name _4: 'Jan-2026'!$DQ$9
Name _5: 'Jan-2026'!$FB$9
Name _6: 'Jan-2026'!$GM$9
Name _7: 'Jan-2026'!$HX$9
Name _8: 'Jan-2026'!$JI$9
Name D: 'Jan-2026'!$A:$A
Name L: 'Jan-2026'!$MC$9
Name S: 'Jan-2026'!$KT:$KT
Name T: 'Jan-2026'!$MM:$MM

Sheet Summary
B1: Ink & Solvent Cost - December 2025 | F1: sample
C2: =SUBTOTAL(9,C4:C1048576) -> 0 | D2: 0 | F2: =SUMIF(D:D,F1,C:C) -> 0 | G2: =+C2-F2 -> 0
B3: WO # | C3: Ink & Solvent Cost (AED) | D3: check
B4: 64411 | C4: =SUMIF(Calculation!$A:$A,Summary!B4,Calculation!$C:$C) -> 0 | D4: SAMPLE
B5: 64437 | C5: =SUMIF(Calculation!$A:$A,Summary!B5,Calculation!$C:$C) -> 0 | D5: SAMPLE
B6: 64438 | C6: =SUMIF(Calculation!$A:$A,Summary!B6,Calculation!$C:$C) -> 0 | D6: SFG
B7: B00694 | C7: =SUMIF(Calculation!$A:$A,Summary!B7,Calculation!$C:$C) -> 0 | D7: SFG
B8: B00857 | C8: =SUMIF(Calculation!$A:$A,Summary!B8,Calculation!$C:$C) -> 0 | D8: SFG
B9: B00858 | C9: =SUMIF(Calculation!$A:$A,Summary!B9,Calculation!$C:$C) -> 0 | D9: SFG
B10: B00957 | C10: =SUMIF(Calculation!$A:$A,Summary!B10,Calculation!$C:$C) -> 0 | D10: SFG
B11: B00966 | C11: =SUMIF(Calculation!$A:$A,Summary!B11,Calculation!$C:$C) -> 0 | D11: SFG
B12: B00970 | C12: =SUMIF(Calculation!$A:$A,Summary!B12,Calculation!$C:$C) -> 0 | D12: SFG
B13: B00978 | C13: =SUMIF(Calculation!$A:$A,Summary!B13,Calculation!$C:$C) -> 0 | D13: SFG
B14: B00981 | C14: =SUMIF(Calculation!$A:$A,Summary!B14,Calculation!$C:$C) -> 0 | D14: SFG
B15: B00985 | C15: =SUMIF(Calculation!$A:$A,Summary!B15,Calculation!$C:$C) -> 0 | D15: SFG
B16: B00990 | C16: =SUMIF(Calculation!$A:$A,Summary!B16,Calculation!$C:$C) -> 0 | D16: SFG
B17: B00992 | C17: =SUMIF(Calculation!$A:$A,Summary!B17,Calculation!$C:$C) -> 0 | D17: SFG
B18: B00993 | C18: =SUMIF(Calculation!$A:$A,Summary!B18,Calculation!$C:$C) -> 0 | D18: SFG
... B438: C01369 | C438: =SUMIF(Calculation!$A:$A,Summary!B438,Calculation!$C:$C) -> 0 | D438: SFG
C439: =SUMIF(Calculation!$A:$A,Summary!B439,Calculation!$C:$C) -> 0
C440: =SUMIF(Calculation!$A:$A,Summary!B440,Calculation!$C:$C) -> 0 | D440: 0
C441: =SUMIF(Calculation!$A:$A,Summary!B441,Calculation!$C:$C) -> 0
C442: =SUMIF(Calculation!$A:$A,Summary!B442,Calculation!$C:$C) -> 0
C443: =SUMIF(Calculation!$A:$A,Summary!B443,Calculation!$C:$C) -> 0 | D443: 0
C444: =SUMIF(Calculation!$A:$A,Summary!B444,Calculation!$C:$C) -> 0
C445: =SUMIF(Calculation!$A:$A,Summary!B445,Calculation!$C:$C) -> 0
C446: =SUMIF(Calculation!$A:$A,Summary!B446,Calculation!$C:$C) -> 0 | D446: 0
C447: =SUMIF(Calculation!$A:$A,Summary!B447,Calculation!$C:$C) -> 0

Sheet Calculation
A2: FILTER ONLY COMBIMED WORK ORDERS AND PASTE BELOW
A3: Row Labels | B3: Sum of x2 | C3: Sum of Value
A4: B00974 | B4: 23900 | C4: 0
A5: B01011 | B5: 8000 | C5: 0
A6: B01018 | B6: 25800 | C6: 0
A7: B01025 | B7: 12600 | C7: 0
A8: B01030 | B8: 60800 | C8: 0
A9: B01031/B01032 | B9: 32850 | C9: 0
A10: B01037 | B10: 29000 | C10: 0
A11: B01038 | B11: 10100 | C11: 0
A12: B01041 | B12: 3500 | C12: 0
A13: B01042 | B13: 36900 | C13: 0
A14: B01043 | B14: 8800 | C14: 0
A15: B01046 | B15: 20100 | C15: 0
... A393: Grand Total | B393: 13565850 | C393: 0
A399: Combined Work Orders | B399: Sum of Mtrs | C399: Sum of Value | D399: Mtr | E399: Value | F399: WO | G399: Mtrs | H399: Amt | I399: WO | J399: Mtrs | K399: Amt | L399: WO | M399: Mtrs | N399: Amt | O399: WO | P399: Mtrs | Q399: Amt | R399: WO | S399: Mtrs | T399: Amt | U399: WO | V399: Mtrs | W399: Amt | X399: WO | Y399: Mtrs | Z399: Amt | AA399: WO | AB399: Mtrs | AC399: Amt | AD399: WO | AE399: Mtrs | AF399: Amt | AG399: WO | AH399: Mtrs | AI399: Amt | AJ399: WO | AK399: Mtrs | AL399: Amt | AM399: WO | AN399: Mtrs | AO399: Amt | AP399: WO | AQ399: Mtrs | AR399: Amt | AS399: WO | AT399: Mtrs | AU399: Amt | AV399: WO | AW399: Mtrs | AX399: Amt | AY399: WO | AZ399: Mtrs | BA399: Amt | BB399: WO | BC399: Mtrs | BD399: Amt | BE399: WO | BF399: Mtrs | BG399: Amt | BH399: WO | BI399: Mtrs | BJ399: Amt | BK399: WO | BL399: Mtrs | BM399: Amt | BN399: WO | BO399: Mtrs | BP399: Amt | BQ399: Total mtrs | BR399: Total amt
D400: =IF(F400<>"",B400-BQ400,0) -> 0 | E400: =IF(F400<>"",C400-H400-K400-N400-Q400-T400-W400-Z400-AC400-AF400-AI400-AL400-AO400-AR400-AU400-AX400-BA400-BD400-BG400-BJ400-BM400-BP400,0) -> 0 | G400: =_xlfn.IFNA(VLOOKUP(F400,Ptd_Mtr!$A:$B,2,FALSE),0) -> 0 | H400: =IF(G400=0,0,G400/$BQ400*$BR400) -> 0 | J400: =_xlfn.IFNA(VLOOKUP(I400,Ptd_Mtr!$A:$B,2,FALSE),0) -> 0 | K400: =IF(J400=0,0,J400/$BQ400*$BR400) -> 0 | M400: =_xlfn.IFNA(VLOOKUP(L400,Ptd_Mtr!$A:$B,2,FALSE),0) -> 0 | N400: =IF(M400=0,0,M400/$BQ400*$BR400) -> 0 | P400: =_xlfn.IFNA(VLOOKUP(O400,Ptd_Mtr!$A:$B,2,FALSE),0) -> 0 | Q400: =IF(P400=0,0,P400/$BQ400*$BR400) -> 0 | S400: =_xlfn.IFNA(VLOOKUP(R400,Ptd_Mtr!$A:$B,2,FALSE),0) -> 0 | T400: =IF(S400=0,0,S400/$BQ400*$BR400) -> 0 | V400: =_xlfn.IFNA(VLOOKUP(U400,Ptd_Mtr!$A:$B,2,FALSE),0) -> 0 | W400: =IF(V400=0,0,V400/$BQ400*$BR400) -> 0 | Y400: =_xlfn.IFNA(VLOOKUP(X400,Ptd_Mtr!$A:$B,2,FALSE),0) -> 0 | Z400: =IF(Y400=0,0,Y400/$BQ400*$BR400) -> 0 | AB400: =_xlfn.IFNA(VLOOKUP(AA400,Ptd_Mtr!$A:$B,2,FALSE),0) -> 0 | AC400: =IF(AB400=0,0,AB400/$BQ400*$BR400) -> 0 | AE400: =_xlfn.IFNA(VLOOKUP(AD400,Ptd_Mtr!$A:$B,2,FALSE),0) -> 0 | AF400: =IF(AE400=0,0,AE400/$BQ400*$BR400) -> 0 | AH400: =_xlfn.IFNA(VLOOKUP(AG400,Ptd_Mtr!$A:$B,2,FALSE),0) -> 0 | AI400: =IF(AH400=0,0,AH400/$BQ400*$BR400) -> 0 | AK400: =_xlfn.IFNA(VLOOKUP(AJ400,Ptd_Mtr!$A:$B,2,FALSE),0) -> 0 | AL400: =IF(AK400=0,0,AK400/$BQ400*$BR400) -> 0 | AN400: =_xlfn.IFNA(VLOOKUP(AM400,Ptd_Mtr!$A:$B,2,FALSE),0) -> 0 | AO400: =IF(AN400=0,0,AN400/$BQ400*$BR400) -> 0 | AQ400: =_xlfn.IFNA(VLOOKUP(AP400,Ptd_Mtr!$A:$B,2,FALSE),0) -> 0 | AR400: =IF(AQ400=0,0,AQ400/$BQ400*$BR400) -> 0 | AT400: =_xlfn.IFNA(VLOOKUP(AS400,Ptd_Mtr!$A:$B,2,FALSE),0) -> 0 | AU400: =IF(AT400=0,0,AT400/$BQ400*$BR400) -> 0 | AW400: =_xlfn.IFNA(VLOOKUP(AV400,Ptd_Mtr!$A:$B,2,FALSE),0) -> 0 | AX400: =IF(AW400=0,0,AW400/$BQ400*$BR400) -> 0 | AZ400: =_xlfn.IFNA(VLOOKUP(AY400,Ptd_Mtr!$A:$B,2,FALSE),0) -> 0 | BA400: =IF(AZ400=0,0,AZ400/$BQ400*$BR400) -> 0 | BC400: =_xlfn.IFNA(VLOOKUP(BB400,Ptd_Mtr!$A:$B,2,FALSE),0) -> 0 | BD400: =IF(BC400=0,0,BC400/$BQ400*$BR400) -> 0 | BF400: =_xlfn.IFNA(VLOOKUP(BE400,Ptd_Mtr!$A:$B,2,FALSE),0) -> 0 | BG400: =IF(BF400=0,0,BF400/$BQ400*$BR400) -> 0 | BI400: =_xlfn.IFNA(VLOOKUP(BH400,Ptd_Mtr!$A:$B,2,FALSE),0) -> 0 | BJ400: =IF(BI400=0,0,BI400/$BQ400*$BR400) -> 0 | BL400: =_xlfn.IFNA(VLOOKUP(BK400,Ptd_Mtr!$A:$B,2,FALSE),0) -> 0 | BM400: =IF(BL400=0,0,BL400/$BQ400*$BR400) -> 0 | BO400: =_xlfn.IFNA(VLOOKUP(BN400,Ptd_Mtr!$A:$B,2,FALSE),0) -> 0 | BP400: =IF(BO400=0,0,BO400/$BQ400*$BR400) -> 0 | BQ400: =+M400+J400+P400+S400+V400+G400+Y400+AB400+AE400+AH400+AK400+AN400+AQ400+AT400+AW400+AZ400+BC400+BF400+BI400+BL400+BO400 -> 0 | BR400: =IF(F400<>"",C400,0) -> 0
D401: =IF(F401<>"",B401-BQ401,0) -> 0 | E401: =IF(F401<>"",C401-H401-K401-N401-Q401-T401-W401-Z401-AC401-AF401-AI401-AL401-AO401-AR401-AU401-AX401-BA401-BD401-BG401-BJ401-BM401-BP401,0) -> 0 | G401: =_xlfn.IFNA(VLOOKUP(F401,Ptd_Mtr!$A:$B,2,FALSE),0) -> 0 | H401: =IF(G401=0,0,G401/$BQ401*$BR401) -> 0 | J401: =_xlfn.IFNA(VLOOKUP(I401,Ptd_Mtr!$A:$B,2,FALSE),0) -> 0 | K401: =IF(J401=0,0,J401/$BQ401*$BR401) -> 0 | M401: =_xlfn.IFNA(VLOOKUP(L401,Ptd_Mtr!$A:$B,2,FALSE),0) -> 0 | N401: =IF(M401=0,0,M401/$BQ401*$BR401) -> 0 | P401: =_xlfn.IFNA(VLOOKUP(O401,Ptd_Mtr!$A:$B,2,FALSE),0) -> 0 | Q401: =IF(P401=0,0,P401/$BQ401*$BR401) -> 0 | S401: =_xlfn.IFNA(VLOOKUP(R401,Ptd_Mtr!$A:$B,2,FALSE),0) -> 0 | T401: =IF(S401=0,0,S401/$BQ401*$BR401) -> 0 | V401: =_xlfn.IFNA(VLOOKUP(U401,Ptd_Mtr!$A:$B,2,FALSE),0) -> 0 | W401: =IF(V401=0,0,V401/$BQ401*$BR401) -> 0 | Y401: =_xlfn.IFNA(VLOOKUP(X401,Ptd_Mtr!$A:$B,2,FALSE),0) -> 0 | Z401: =IF(Y401=0,0,Y401/$BQ401*$BR401) -> 0 | AB401: =_xlfn.IFNA(VLOOKUP(AA401,Ptd_Mtr!$A:$B,2,FALSE),0) -> 0 | AC401: =IF(AB401=0,0,AB401/$BQ401*$BR401) -> 0 | AE401: =_xlfn.IFNA(VLOOKUP(AD401,Ptd_Mtr!$A:$B,2,FALSE),0) -> 0 | AF401: =IF(AE401=0,0,AE401/$BQ401*$BR401) -> 0 | AH401: =_xlfn.IFNA(VLOOKUP(AG401,Ptd_Mtr!$A:$B,2,FALSE),0) -> 0 | AI401: =IF(AH401=0,0,AH401/$BQ401*$BR401) -> 0 | AK401: =_xlfn.IFNA(VLOOKUP(AJ401,Ptd_Mtr!$A:$B,2,FALSE),0) -> 0 | AL401: =IF(AK401=0,0,AK401/$BQ401*$BR401) -> 0 | AN401: =_xlfn.IFNA(VLOOKUP(AM401,Ptd_Mtr!$A:$B,2,FALSE),0) -> 0 | AO401: =IF(AN401=0,0,AN401/$BQ401*$BR401) -> 0 | AQ401: =_xlfn.IFNA(VLOOKUP(AP401,Ptd_Mtr!$A:$B,2,FALSE),0) -> 0 | AR401: =IF(AQ401=0,0,AQ401/$BQ401*$BR401) -> 0 | AT401: =_xlfn.IFNA(VLOOKUP(AS401,Ptd_Mtr!$A:$B,2,FALSE),0) -> 0 | AU401: =IF(AT401=0,0,AT401/$BQ401*$BR401) -> 0 | AW401: =_xlfn.IFNA(VLOOKUP(AV401,Ptd_Mtr!$A:$B,2,FALSE),0) -> 0 | AX401: =IF(AW401=0,0,AW401/$BQ401*$BR401) -> 0 | AZ401: =_xlfn.IFNA(VLOOKUP(AY401,Ptd_Mtr!$A:$B,2,FALSE),0) -> 0 | BA401: =IF(AZ401=0,0,AZ401/$BQ401*$BR401) -> 0 | BC401: =_xlfn.IFNA(VLOOKUP(BB401,Ptd_Mtr!$A:$B,2,FALSE),0) -> 0 | BD401: =IF(BC401=0,0,BC401/$BQ401*$BR401) -> 0 | BF401: =_xlfn.IFNA(VLOOKUP(BE401,Ptd_Mtr!$A:$B,2,FALSE),0) -> 0 | BG401: =IF(BF401=0,0,BF401/$BQ401*$BR401) -> 0 | BI401: =_xlfn.IFNA(VLOOKUP(BH401,Ptd_Mtr!$A:$B,2,FALSE),0) -> 0 | BJ401: =IF(BI401=0,0,BI401/$BQ401*$BR401) -> 0 | BL401: =_xlfn.IFNA(VLOOKUP(BK401,Ptd_Mtr!$A:$B,2,FALSE),0) -> 0 | BM401: =IF(BL401=0,0,BL401/$BQ401*$BR401) -> 0 | BO401: =_xlfn.IFNA(VLOOKUP(BN401,Ptd_Mtr!$A:$B,2,FALSE),0) -> 0 | BP401: =IF(BO401=0,0,BO401/$BQ401*$BR401) -> 0 | BQ401: =+M401+J401+P401+S401+V401+G401+Y401+AB401+AE401+AH401+AK401+AN401+AQ401+AT401+AW401+AZ401+BC401+BF401+BI401+BL401+BO401 -> 0 | BR401: =IF(F401<>"",C401,0) -> 0
D402: =IF(F402<>"",B402-BQ402,0) -> 0 | E402: =IF(F402<>"",C402-H402-K402-N402-Q402-T402-W402-Z402-AC402-AF402-AI402-AL402-AO402-AR402-AU402-AX402-BA402-BD402-BG402-BJ402-BM402-BP402,0) -> 0 | G402: =_xlfn.IFNA(VLOOKUP(F402,Ptd_Mtr!$A:$B,2,FALSE),0) -> 0 | H402: =IF(G402=0,0,G402/$BQ402*$BR402) -> 0 | J402: =_xlfn.IFNA(VLOOKUP(I402,Ptd_Mtr!$A:$B,2,FALSE),0) -> 0 | K402: =IF(J402=0,0,J402/$BQ402*$BR402) -> 0 | M402: =_xlfn.IFNA(VLOOKUP(L402,Ptd_Mtr!$A:$B,2,FALSE),0) -> 0 | N402: =IF(M402=0,0,M402/$BQ402*$BR402) -> 0 | P402: =_xlfn.IFNA(VLOOKUP(O402,Ptd_Mtr!$A:$B,2,FALSE),0) -> 0 | Q402: =IF(P402=0,0,P402/$BQ402*$BR402) -> 0 | S402: =_xlfn.IFNA(VLOOKUP(R402,Ptd_Mtr!$A:$B,2,FALSE),0) -> 0 | T402: =IF(S402=0,0,S402/$BQ402*$BR402) -> 0 | V402: =_xlfn.IFNA(VLOOKUP(U402,Ptd_Mtr!$A:$B,2,FALSE),0) -> 0 | W402: =IF(V402=0,0,V402/$BQ402*$BR402) -> 0 | Y402: =_xlfn.IFNA(VLOOKUP(X402,Ptd_Mtr!$A:$B,2,FALSE),0) -> 0 | Z402: =IF(Y402=0,0,Y402/$BQ402*$BR402) -> 0 | AB402: =_xlfn.IFNA(VLOOKUP(AA402,Ptd_Mtr!$A:$B,2,FALSE),0) -> 0 | AC402: =IF(AB402=0,0,AB402/$BQ402*$BR402) -> 0 | AE402: =_xlfn.IFNA(VLOOKUP(AD402,Ptd_Mtr!$A:$B,2,FALSE),0) -> 0 | AF402: =IF(AE402=0,0,AE402/$BQ402*$BR402) -> 0 | AH402: =_xlfn.IFNA(VLOOKUP(AG402,Ptd_Mtr!$A:$B,2,FALSE),0) -> 0 | AI402: =IF(AH402=0,0,AH402/$BQ402*$BR402) -> 0 | AK402: =_xlfn.IFNA(VLOOKUP(AJ402,Ptd_Mtr!$A:$B,2,FALSE),0) -> 0 | AL402: =IF(AK402=0,0,AK402/$BQ402*$BR402) -> 0 | AN402: =_xlfn.IFNA(VLOOKUP(AM402,Ptd_Mtr!$A:$B,2,FALSE),0) -> 0 | AO402: =IF(AN402=0,0,AN402/$BQ402*$BR402) -> 0 | AQ402: =_xlfn.IFNA(VLOOKUP(AP402,Ptd_Mtr!$A:$B,2,FALSE),0) -> 0 | AR402: =IF(AQ402=0,0,AQ402/$BQ402*$BR402) -> 0 | AT402: =_xlfn.IFNA(VLOOKUP(AS402,Ptd_Mtr!$A:$B,2,FALSE),0) -> 0 | AU402: =IF(AT402=0,0,AT402/$BQ402*$BR402) -> 0 | AW402: =_xlfn.IFNA(VLOOKUP(AV402,Ptd_Mtr!$A:$B,2,FALSE),0) -> 0 | AX402: =IF(AW402=0,0,AW402/$BQ402*$BR402) -> 0 | AZ402: =_xlfn.IFNA(VLOOKUP(AY402,Ptd_Mtr!$A:$B,2,FALSE),0) -> 0 | BA402: =IF(AZ402=0,0,AZ402/$BQ402*$BR402) -> 0 | BC402: =_xlfn.IFNA(VLOOKUP(BB402,Ptd_Mtr!$A:$B,2,FALSE),0) -> 0 | BD402: =IF(BC402=0,0,BC402/$BQ402*$BR402) -> 0 | BF402: =_xlfn.IFNA(VLOOKUP(BE402,Ptd_Mtr!$A:$B,2,FALSE),0) -> 0 | BG402: =IF(BF402=0,0,BF402/$BQ402*$BR402) -> 0 | BI402: =_xlfn.IFNA(VLOOKUP(BH402,Ptd_Mtr!$A:$B,2,FALSE),0) -> 0 | BJ402: =IF(BI402=0,0,BI402/$BQ402*$BR402) -> 0 | BL402: =_xlfn.IFNA(VLOOKUP(BK402,Ptd_Mtr!$A:$B,2,FALSE),0) -> 0 | BM402: =IF(BL402=0,0,BL402/$BQ402*$BR402) -> 0 | BO402: =_xlfn.IFNA(VLOOKUP(BN402,Ptd_Mtr!$A:$B,2,FALSE),0) -> 0 | BP402: =IF(BO402=0,0,BO402/$BQ402*$BR402) -> 0 | BQ402: =+M402+J402+P402+S402+V402+G402+Y402+AB402+AE402+AH402+AK402+AN402+AQ402+AT402+AW402+AZ402+BC402+BF402+BI402+BL402+BO402 -> 0 | BR402: =IF(F402<>"",C402,0) -> 0
D403: =IF(F403<>"",B403-BQ403,0) -> 0 | E403: =IF(F403<>"",C403-H403-K403-N403-Q403-T403-W403-Z403-AC403-AF403-AI403-AL403-AO403-AR403-AU403-AX403-BA403-BD403-BG403-BJ403-BM403-BP403,0) -> 0 | G403: =_xlfn.IFNA(VLOOKUP(F403,Ptd_Mtr!$A:$B,2,FALSE),0) -> 0 | H403: =IF(G403=0,0,G403/$BQ403*$BR403) -> 0 | J403: =_xlfn.IFNA(VLOOKUP(I403,Ptd_Mtr!$A:$B,2,FALSE),0) -> 0 | K403: =IF(J403=0,0,J403/$BQ403*$BR403) -> 0 | M403: =_xlfn.IFNA(VLOOKUP(L403,Ptd_Mtr!$A:$B,2,FALSE),0) -> 0 | N403: =IF(M403=0,0,M403/$BQ403*$BR403) -> 0 | P403: =_xlfn.IFNA(VLOOKUP(O403,Ptd_Mtr!$A:$B,2,FALSE),0) -> 0 | Q403: =IF(P403=0,0,P403/$BQ403*$BR403) -> 0 | S403: =_xlfn.IFNA(VLOOKUP(R403,Ptd_Mtr!$A:$B,2,FALSE),0) -> 0 | T403: =IF(S403=0,0,S403/$BQ403*$BR403) -> 0 | V403: =_xlfn.IFNA(VLOOKUP(U403,Ptd_Mtr!$A:$B,2,FALSE),0) -> 0 | W403: =IF(V403=0,0,V403/$BQ403*$BR403) -> 0 | Y403: =_xlfn.IFNA(VLOOKUP(X403,Ptd_Mtr!$A:$B,2,FALSE),0) -> 0 | Z403: =IF(Y403=0,0,Y403/$BQ403*$BR403) -> 0 | AB403: =_xlfn.IFNA(VLOOKUP(AA403,Ptd_Mtr!$A:$B,2,FALSE),0) -> 0 | AC403: =IF(AB403=0,0,AB403/$BQ403*$BR403) -> 0 | AE403: =_xlfn.IFNA(VLOOKUP(AD403,Ptd_Mtr!$A:$B,2,FALSE),0) -> 0 | AF403: =IF(AE403=0,0,AE403/$BQ403*$BR403) -> 0 | AH403: =_xlfn.IFNA(VLOOKUP(AG403,Ptd_Mtr!$A:$B,2,FALSE),0) -> 0 | AI403: =IF(AH403=0,0,AH403/$BQ403*$BR403) -> 0 | AK403: =_xlfn.IFNA(VLOOKUP(AJ403,Ptd_Mtr!$A:$B,2,FALSE),0) -> 0 | AL403: =IF(AK403=0,0,AK403/$BQ403*$BR403) -> 0 | AN403: =_xlfn.IFNA(VLOOKUP(AM403,Ptd_Mtr!$A:$B,2,FALSE),0) -> 0 | AO403: =IF(AN403=0,0,AN403/$BQ403*$BR403) -> 0 | AQ403: =_xlfn.IFNA(VLOOKUP(AP403,Ptd_Mtr!$A:$B,2,FALSE),0) -> 0 | AR403: =IF(AQ403=0,0,AQ403/$BQ403*$BR403) -> 0 | AT403: =_xlfn.IFNA(VLOOKUP(AS403,Ptd_Mtr!$A:$B,2,FALSE),0) -> 0 | AU403: =IF(AT403=0,0,AT403/$BQ403*$BR403) -> 0 | AW403: =_xlfn.IFNA(VLOOKUP(AV403,Ptd_Mtr!$A:$B,2,FALSE),0) -> 0 | AX403: =IF(AW403=0,0,AW403/$BQ403*$BR403) -> 0 | AZ403: =_xlfn.IFNA(VLOOKUP(AY403,Ptd_Mtr!$A:$B,2,FALSE),0) -> 0 | BA403: =IF(AZ403=0,0,AZ403/$BQ403*$BR403) -> 0 | BC403: =_xlfn.IFNA(VLOOKUP(BB403,Ptd_Mtr!$A:$B,2,FALSE),0) -> 0 | BD403: =IF(BC403=0,0,BC403/$BQ403*$BR403) -> 0 | BF403: =_xlfn.IFNA(VLOOKUP(BE403,Ptd_Mtr!$A:$B,2,FALSE),0) -> 0 | BG403: =IF(BF403=0,0,BF403/$BQ403*$BR403) -> 0 | BI403: =_xlfn.IFNA(VLOOKUP(BH403,Ptd_Mtr!$A:$B,2,FALSE),0) -> 0 | BJ403: =IF(BI403=0,0,BI403/$BQ403*$BR403) -> 0 | BL403: =_xlfn.IFNA(VLOOKUP(BK403,Ptd_Mtr!$A:$B,2,FALSE),0) -> 0 | BM403: =IF(BL403=0,0,BL403/$BQ403*$BR403) -> 0 | BO403: =_xlfn.IFNA(VLOOKUP(BN403,Ptd_Mtr!$A:$B,2,FALSE),0) -> 0 | BP403: =IF(BO403=0,0,BO403/$BQ403*$BR403) -> 0 | BQ403: =+M403+J403+P403+S403+V403+G403+Y403+AB403+AE403+AH403+AK403+AN403+AQ403+AT403+AW403+AZ403+BC403+BF403+BI403+BL403+BO403 -> 0 | BR403: =IF(F403<>"",C403,0) -> 0
D404: =IF(F404<>"",B404-BQ404,0) -> 0 | E404: =IF(F404<>"",C404-H404-K404-N404-Q404-T404-W404-Z404-AC404-AF404-AI404-AL404-AO404-AR404-AU404-AX404-BA404-BD404-BG404-BJ404-BM404-BP404,0) -> 0 | G404: =_xlfn.IFNA(VLOOKUP(F404,Ptd_Mtr!$A:$B,2,FALSE),0) -> 0 | H404: =IF(G404=0,0,G404/$BQ404*$BR404) -> 0 | J404: =_xlfn.IFNA(VLOOKUP(I404,Ptd_Mtr!$A:$B,2,FALSE),0) -> 0 | K404: =IF(J404=0,0,J404/$BQ404*$BR404) -> 0 | M404: =_xlfn.IFNA(VLOOKUP(L404,Ptd_Mtr!$A:$B,2,FALSE),0) -> 0 | N404: =IF(M404=0,0,M404/$BQ404*$BR404) -> 0 | P404: =_xlfn.IFNA(VLOOKUP(O404,Ptd_Mtr!$A:$B,2,FALSE),0) -> 0 | Q404: =IF(P404=0,0,P404/$BQ404*$BR404) -> 0 | S404: =_xlfn.IFNA(VLOOKUP(R404,Ptd_Mtr!$A:$B,2,FALSE),0) -> 0 | T404: =IF(S404=0,0,S404/$BQ404*$BR404) -> 0 | V404: =_xlfn.IFNA(VLOOKUP(U404,Ptd_Mtr!$A:$B,2,FALSE),0) -> 0 | W404: =IF(V404=0,0,V404/$BQ404*$BR404) -> 0 | Y404: =_xlfn.IFNA(VLOOKUP(X404,Ptd_Mtr!$A:$B,2,FALSE),0) -> 0 | Z404: =IF(Y404=0,0,Y404/$BQ404*$BR404) -> 0 | AB404: =_xlfn.IFNA(VLOOKUP(AA404,Ptd_Mtr!$A:$B,2,FALSE),0) -> 0 | AC404: =IF(AB404=0,0,AB404/$BQ404*$BR404) -> 0 | AE404: =_xlfn.IFNA(VLOOKUP(AD404,Ptd_Mtr!$A:$B,2,FALSE),0) -> 0 | AF404: =IF(AE404=0,0,AE404/$BQ404*$BR404) -> 0 | AH404: =_xlfn.IFNA(VLOOKUP(AG404,Ptd_Mtr!$A:$B,2,FALSE),0) -> 0 | AI404: =IF(AH404=0,0,AH404/$BQ404*$BR404) -> 0 | AK404: =_xlfn.IFNA(VLOOKUP(AJ404,Ptd_Mtr!$A:$B,2,FALSE),0) -> 0 | AL404: =IF(AK404=0,0,AK404/$BQ404*$BR404) -> 0 | AN404: =_xlfn.IFNA(VLOOKUP(AM404,Ptd_Mtr!$A:$B,2,FALSE),0) -> 0 | AO404: =IF(AN404=0,0,AN404/$BQ404*$BR404) -> 0 | AQ404: =_xlfn.IFNA(VLOOKUP(AP404,Ptd_Mtr!$A:$B,2,FALSE),0) -> 0 | AR404: =IF(AQ404=0,0,AQ404/$BQ404*$BR404) -> 0 | AT404: =_xlfn.IFNA(VLOOKUP(AS404,Ptd_Mtr!$A:$B,2,FALSE),0) -> 0 | AU404: =IF(AT404=0,0,AT404/$BQ404*$BR404) -> 0 | AW404: =_xlfn.IFNA(VLOOKUP(AV404,Ptd_Mtr!$A:$B,2,FALSE),0) -> 0 | AX404: =IF(AW404=0,0,AW404/$BQ404*$BR404) -> 0 | AZ404: =_xlfn.IFNA(VLOOKUP(AY404,Ptd_Mtr!$A:$B,2,FALSE),0) -> 0 | BA404: =IF(AZ404=0,0,AZ404/$BQ404*$BR404) -> 0 | BC404: =_xlfn.IFNA(VLOOKUP(BB404,Ptd_Mtr!$A:$B,2,FALSE),0) -> 0 | BD404: =IF(BC404=0,0,BC404/$BQ404*$BR404) -> 0 | BF404: =_xlfn.IFNA(VLOOKUP(BE404,Ptd_Mtr!$A:$B,2,FALSE),0) -> 0 | BG404: =IF(BF404=0,0,BF404/$BQ404*$BR404) -> 0 | BI404: =_xlfn.IFNA(VLOOKUP(BH404,Ptd_Mtr!$A:$B,2,FALSE),0) -> 0 | BJ404: =IF(BI404=0,0,BI404/$BQ404*$BR404) -> 0 | BL404: =_xlfn.IFNA(VLOOKUP(BK404,Ptd_Mtr!$A:$B,2,FALSE),0) -> 0 | BM404: =IF(BL404=0,0,BL404/$BQ404*$BR404) -> 0 | BO404: =_xlfn.IFNA(VLOOKUP(BN404,Ptd_Mtr!$A:$B,2,FALSE),0) -> 0 | BP404: =IF(BO404=0,0,BO404/$BQ404*$BR404) -> 0 | BQ404: =+M404+J404+P404+S404+V404+G404+Y404+AB404+AE404+AH404+AK404+AN404+AQ404+AT404+AW404+AZ404+BC404+BF404+BI404+BL404+BO404 -> 0 | BR404: =IF(F404<>"",C404,0) -> 0
D405: =IF(F405<>"",B405-BQ405,0) -> 0 | E405: =IF(F405<>"",C405-H405-K405-N405-Q405-T405-W405-Z405-AC405-AF405-AI405-AL405-AO405-AR405-AU405-AX405-BA405-BD405-BG405-BJ405-BM405-BP405,0) -> 0 | G405: =_xlfn.IFNA(VLOOKUP(F405,Ptd_Mtr!$A:$B,2,FALSE),0) -> 0 | H405: =IF(G405=0,0,G405/$BQ405*$BR405) -> 0 | J405: =_xlfn.IFNA(VLOOKUP(I405,Ptd_Mtr!$A:$B,2,FALSE),0) -> 0 | K405: =IF(J405=0,0,J405/$BQ405*$BR405) -> 0 | M405: =_xlfn.IFNA(VLOOKUP(L405,Ptd_Mtr!$A:$B,2,FALSE),0) -> 0 | N405: =IF(M405=0,0,M405/$BQ405*$BR405) -> 0 | P405: =_xlfn.IFNA(VLOOKUP(O405,Ptd_Mtr!$A:$B,2,FALSE),0) -> 0 | Q405: =IF(P405=0,0,P405/$BQ405*$BR405) -> 0 | S405: =_xlfn.IFNA(VLOOKUP(R405,Ptd_Mtr!$A:$B,2,FALSE),0) -> 0 | T405: =IF(S405=0,0,S405/$BQ405*$BR405) -> 0 | V405: =_xlfn.IFNA(VLOOKUP(U405,Ptd_Mtr!$A:$B,2,FALSE),0) -> 0 | W405: =IF(V405=0,0,V405/$BQ405*$BR405) -> 0 | Y405: =_xlfn.IFNA(VLOOKUP(X405,Ptd_Mtr!$A:$B,2,FALSE),0) -> 0 | Z405: =IF(Y405=0,0,Y405/$BQ405*$BR405) -> 0 | AB405: =_xlfn.IFNA(VLOOKUP(AA405,Ptd_Mtr!$A:$B,2,FALSE),0) -> 0 | AC405: =IF(AB405=0,0,AB405/$BQ405*$BR405) -> 0 | AE405: =_xlfn.IFNA(VLOOKUP(AD405,Ptd_Mtr!$A:$B,2,FALSE),0) -> 0 | AF405: =IF(AE405=0,0,AE405/$BQ405*$BR405) -> 0 | AH405: =_xlfn.IFNA(VLOOKUP(AG405,Ptd_Mtr!$A:$B,2,FALSE),0) -> 0 | AI405: =IF(AH405=0,0,AH405/$BQ405*$BR405) -> 0 | AK405: =_xlfn.IFNA(VLOOKUP(AJ405,Ptd_Mtr!$A:$B,2,FALSE),0) -> 0 | AL405: =IF(AK405=0,0,AK405/$BQ405*$BR405) -> 0 | AN405: =_xlfn.IFNA(VLOOKUP(AM405,Ptd_Mtr!$A:$B,2,FALSE),0) -> 0 | AO405: =IF(AN405=0,0,AN405/$BQ405*$BR405) -> 0 | AQ405: =_xlfn.IFNA(VLOOKUP(AP405,Ptd_Mtr!$A:$B,2,FALSE),0) -> 0 | AR405: =IF(AQ405=0,0,AQ405/$BQ405*$BR405) -> 0 | AT405: =_xlfn.IFNA(VLOOKUP(AS405,Ptd_Mtr!$A:$B,2,FALSE),0) -> 0 | AU405: =IF(AT405=0,0,AT405/$BQ405*$BR405) -> 0 | AW405: =_xlfn.IFNA(VLOOKUP(AV405,Ptd_Mtr!$A:$B,2,FALSE),0) -> 0 | AX405: =IF(AW405=0,0,AW405/$BQ405*$BR405) -> 0 | AZ405: =_xlfn.IFNA(VLOOKUP(AY405,Ptd_Mtr!$A:$B,2,FALSE),0) -> 0 | BA405: =IF(AZ405=0,0,AZ405/$BQ405*$BR405) -> 0 | BC405: =_xlfn.IFNA(VLOOKUP(BB405,Ptd_Mtr!$A:$B,2,FALSE),0) -> 0 | BD405: =IF(BC405=0,0,BC405/$BQ405*$BR405) -> 0 | BF405: =_xlfn.IFNA(VLOOKUP(BE405,Ptd_Mtr!$A:$B,2,FALSE),0) -> 0 | BG405: =IF(BF405=0,0,BF405/$BQ405*$BR405) -> 0 | BI405: =_xlfn.IFNA(VLOOKUP(BH405,Ptd_Mtr!$A:$B,2,FALSE),0) -> 0 | BJ405: =IF(BI405=0,0,BI405/$BQ405*$BR405) -> 0 | BL405: =_xlfn.IFNA(VLOOKUP(BK405,Ptd_Mtr!$A:$B,2,FALSE),0) -> 0 | BM405: =IF(BL405=0,0,BL405/$BQ405*$BR405) -> 0 | BO405: =_xlfn.IFNA(VLOOKUP(BN405,Ptd_Mtr!$A:$B,2,FALSE),0) -> 0 | BP405: =IF(BO405=0,0,BO405/$BQ405*$BR405) -> 0 | BQ405: =+M405+J405+P405+S405+V405+G405+Y405+AB405+AE405+AH405+AK405+AN405+AQ405+AT405+AW405+AZ405+BC405+BF405+BI405+BL405+BO405 -> 0 | BR405: =IF(F405<>"",C405,0) -> 0
D406: =IF(F406<>"",B406-BQ406,0) -> 0 | E406: =IF(F406<>"",C406-H406-K406-N406-Q406-T406-W406-Z406-AC406-AF406-AI406-AL406-AO406-AR406-AU406-AX406-BA406-BD406-BG406-BJ406-BM406-BP406,0) -> 0 | G406: =_xlfn.IFNA(VLOOKUP(F406,Ptd_Mtr!$A:$B,2,FALSE),0) -> 0 | H406: =IF(G406=0,0,G406/$BQ406*$BR406) -> 0 | J406: =_xlfn.IFNA(VLOOKUP(I406,Ptd_Mtr!$A:$B,2,FALSE),0) -> 0 | K406: =IF(J406=0,0,J406/$BQ406*$BR406) -> 0 | M406: =_xlfn.IFNA(VLOOKUP(L406,Ptd_Mtr!$A:$B,2,FALSE),0) -> 0 | N406: =IF(M406=0,0,M406/$BQ406*$BR406) -> 0 | P406: =_xlfn.IFNA(VLOOKUP(O406,Ptd_Mtr!$A:$B,2,FALSE),0) -> 0 | Q406: =IF(P406=0,0,P406/$BQ406*$BR406) -> 0 | S406: =_xlfn.IFNA(VLOOKUP(R406,Ptd_Mtr!$A:$B,2,FALSE),0) -> 0 | T406: =IF(S406=0,0,S406/$BQ406*$BR406) -> 0 | V406: =_xlfn.IFNA(VLOOKUP(U406,Ptd_Mtr!$A:$B,2,FALSE),0) -> 0 | W406: =IF(V406=0,0,V406/$BQ406*$BR406) -> 0 | Y406: =_xlfn.IFNA(VLOOKUP(X406,Ptd_Mtr!$A:$B,2,FALSE),0) -> 0 | Z406: =IF(Y406=0,0,Y406/$BQ406*$BR406) -> 0 | AB406: =_xlfn.IFNA(VLOOKUP(AA406,Ptd_Mtr!$A:$B,2,FALSE),0) -> 0 | AC406: =IF(AB406=0,0,AB406/$BQ406*$BR406) -> 0 | AE406: =_xlfn.IFNA(VLOOKUP(AD406,Ptd_Mtr!$A:$B,2,FALSE),0) -> 0 | AF406: =IF(AE406=0,0,AE406/$BQ406*$BR406) -> 0 | AH406: =_xlfn.IFNA(VLOOKUP(AG406,Ptd_Mtr!$A:$B,2,FALSE),0) -> 0 | AI406: =IF(AH406=0,0,AH406/$BQ406*$BR406) -> 0 | AK406: =_xlfn.IFNA(VLOOKUP(AJ406,Ptd_Mtr!$A:$B,2,FALSE),0) -> 0 | AL406: =IF(AK406=0,0,AK406/$BQ406*$BR406) -> 0 | AN406: =_xlfn.IFNA(VLOOKUP(AM406,Ptd_Mtr!$A:$B,2,FALSE),0) -> 0 | AO406: =IF(AN406=0,0,AN406/$BQ406*$BR406) -> 0 | AQ406: =_xlfn.IFNA(VLOOKUP(AP406,Ptd_Mtr!$A:$B,2,FALSE),0) -> 0 | AR406: =IF(AQ406=0,0,AQ406/$BQ406*$BR406) -> 0 | AT406: =_xlfn.IFNA(VLOOKUP(AS406,Ptd_Mtr!$A:$B,2,FALSE),0) -> 0 | AU406: =IF(AT406=0,0,AT406/$BQ406*$BR406) -> 0 | AW406: =_xlfn.IFNA(VLOOKUP(AV406,Ptd_Mtr!$A:$B,2,FALSE),0) -> 0 | AX406: =IF(AW406=0,0,AW406/$BQ406*$BR406) -> 0 | AZ406: =_xlfn.IFNA(VLOOKUP(AY406,Ptd_Mtr!$A:$B,2,FALSE),0) -> 0 | BA406: =IF(AZ406=0,0,AZ406/$BQ406*$BR406) -> 0 | BC406: =_xlfn.IFNA(VLOOKUP(BB406,Ptd_Mtr!$A:$B,2,FALSE),0) -> 0 | BD406: =IF(BC406=0,0,BC406/$BQ406*$BR406) -> 0 | BF406: =_xlfn.IFNA(VLOOKUP(BE406,Ptd_Mtr!$A:$B,2,FALSE),0) -> 0 | BG406: =IF(BF406=0,0,BF406/$BQ406*$BR406) -> 0 | BI406: =_xlfn.IFNA(VLOOKUP(BH406,Ptd_Mtr!$A:$B,2,FALSE),0) -> 0 | BJ406: =IF(BI406=0,0,BI406/$BQ406*$BR406) -> 0 | BL406: =_xlfn.IFNA(VLOOKUP(BK406,Ptd_Mtr!$A:$B,2,FALSE),0) -> 0 | BM406: =IF(BL406=0,0,BL406/$BQ406*$BR406) -> 0 | BO406: =_xlfn.IFNA(VLOOKUP(BN406,Ptd_Mtr!$A:$B,2,FALSE),0) -> 0 | BP406: =IF(BO406=0,0,BO406/$BQ406*$BR406) -> 0 | BQ406: =+M406+J406+P406+S406+V406+G406+Y406+AB406+AE406+AH406+AK406+AN406+AQ406+AT406+AW406+AZ406+BC406+BF406+BI406+BL406+BO406 -> 0 | BR406: =IF(F406<>"",C406,0) -> 0
D407: =IF(F407<>"",B407-BQ407,0) -> 0 | E407: =IF(F407<>"",C407-H407-K407-N407-Q407-T407-W407-Z407-AC407-AF407-AI407-AL407-AO407-AR407-AU407-AX407-BA407-BD407-BG407-BJ407-BM407-BP407,0) -> 0 | G407: =_xlfn.IFNA(VLOOKUP(F407,Ptd_Mtr!$A:$B,2,FALSE),0) -> 0 | H407: =IF(G407=0,0,G407/$BQ407*$BR407) -> 0 | J407: =_xlfn.IFNA(VLOOKUP(I407,Ptd_Mtr!$A:$B,2,FALSE),0) -> 0 | K407: =IF(J407=0,0,J407/$BQ407*$BR407) -> 0 | M407: =_xlfn.IFNA(VLOOKUP(L407,Ptd_Mtr!$A:$B,2,FALSE),0) -> 0 | N407: =IF(M407=0,0,M407/$BQ407*$BR407) -> 0 | P407: =_xlfn.IFNA(VLOOKUP(O407,Ptd_Mtr!$A:$B,2,FALSE),0) -> 0 | Q407: =IF(P407=0,0,P407/$BQ407*$BR407) -> 0 | S407: =_xlfn.IFNA(VLOOKUP(R407,Ptd_Mtr!$A:$B,2,FALSE),0) -> 0 | T407: =IF(S407=0,0,S407/$BQ407*$BR407) -> 0 | V407: =_xlfn.IFNA(VLOOKUP(U407,Ptd_Mtr!$A:$B,2,FALSE),0) -> 0 | W407: =IF(V407=0,0,V407/$BQ407*$BR407) -> 0 | Y407: =_xlfn.IFNA(VLOOKUP(X407,Ptd_Mtr!$A:$B,2,FALSE),0) -> 0 | Z407: =IF(Y407=0,0,Y407/$BQ407*$BR407) -> 0 | AB407: =_xlfn.IFNA(VLOOKUP(AA407,Ptd_Mtr!$A:$B,2,FALSE),0) -> 0 | AC407: =IF(AB407=0,0,AB407/$BQ407*$BR407) -> 0 | AE407: =_xlfn.IFNA(VLOOKUP(AD407,Ptd_Mtr!$A:$B,2,FALSE),0) -> 0 | AF407: =IF(AE407=0,0,AE407/$BQ407*$BR407) -> 0 | AH407: =_xlfn.IFNA(VLOOKUP(AG407,Ptd_Mtr!$A:$B,2,FALSE),0) -> 0 | AI407: =IF(AH407=0,0,AH407/$BQ407*$BR407) -> 0 | AK407: =_xlfn.IFNA(VLOOKUP(AJ407,Ptd_Mtr!$A:$B,2,FALSE),0) -> 0 | AL407: =IF(AK407=0,0,AK407/$BQ407*$BR407) -> 0 | AN407: =_xlfn.IFNA(VLOOKUP(AM407,Ptd_Mtr!$A:$B,2,FALSE),0) -> 0 | AO407: =IF(AN407=0,0,AN407/$BQ407*$BR407) -> 0 | AQ407: =_xlfn.IFNA(VLOOKUP(AP407,Ptd_Mtr!$A:$B,2,FALSE),0) -> 0 | AR407: =IF(AQ407=0,0,AQ407/$BQ407*$BR407) -> 0 | AT407: =_xlfn.IFNA(VLOOKUP(AS407,Ptd_Mtr!$A:$B,2,FALSE),0) -> 0 | AU407: =IF(AT407=0,0,AT407/$BQ407*$BR407) -> 0 | AW407: =_xlfn.IFNA(VLOOKUP(AV407,Ptd_Mtr!$A:$B,2,FALSE),0) -> 0 | AX407: =IF(AW407=0,0,AW407/$BQ407*$BR407) -> 0 | AZ407: =_xlfn.IFNA(VLOOKUP(AY407,Ptd_Mtr!$A:$B,2,FALSE),0) -> 0 | BA407: =IF(AZ407=0,0,AZ407/$BQ407*$BR407) -> 0 | BC407: =_xlfn.IFNA(VLOOKUP(BB407,Ptd_Mtr!$A:$B,2,FALSE),0) -> 0 | BD407: =IF(BC407=0,0,BC407/$BQ407*$BR407) -> 0 | BF407: =_xlfn.IFNA(VLOOKUP(BE407,Ptd_Mtr!$A:$B,2,FALSE),0) -> 0 | BG407: =IF(BF407=0,0,BF407/$BQ407*$BR407) -> 0 | BI407: =_xlfn.IFNA(VLOOKUP(BH407,Ptd_Mtr!$A:$B,2,FALSE),0) -> 0 | BJ407: =IF(BI407=0,0,BI407/$BQ407*$BR407) -> 0 | BL407: =_xlfn.IFNA(VLOOKUP(BK407,Ptd_Mtr!$A:$B,2,FALSE),0) -> 0 | BM407: =IF(BL407=0,0,BL407/$BQ407*$BR407) -> 0 | BO407: =_xlfn.IFNA(VLOOKUP(BN407,Ptd_Mtr!$A:$B,2,FALSE),0) -> 0 | BP407: =IF(BO407=0,0,BO407/$BQ407*$BR407) -> 0 | BQ407: =+M407+J407+P407+S407+V407+G407+Y407+AB407+AE407+AH407+AK407+AN407+AQ407+AT407+AW407+AZ407+BC407+BF407+BI407+BL407+BO407 -> 0 | BR407: =IF(F407<>"",C407,0) -> 0
D408: =IF(F408<>"",B408-BQ408,0) -> 0 | E408: =IF(F408<>"",C408-H408-K408-N408-Q408-T408-W408-Z408-AC408-AF408-AI408-AL408-AO408-AR408-AU408-AX408-BA408-BD408-BG408-BJ408-BM408-BP408,0) -> 0 | G408: =_xlfn.IFNA(VLOOKUP(F408,Ptd_Mtr!$A:$B,2,FALSE),0) -> 0 | H408: =IF(G408=0,0,G408/$BQ408*$BR408) -> 0 | J408: =_xlfn.IFNA(VLOOKUP(I408,Ptd_Mtr!$A:$B,2,FALSE),0) -> 0 | K408: =IF(J408=0,0,J408/$BQ408*$BR408) -> 0 | M408: =_xlfn.IFNA(VLOOKUP(L408,Ptd_Mtr!$A:$B,2,FALSE),0) -> 0 | N408: =IF(M408=0,0,M408/$BQ408*$BR408) -> 0 | P408: =_xlfn.IFNA(VLOOKUP(O408,Ptd_Mtr!$A:$B,2,FALSE),0) -> 0 | Q408: =IF(P408=0,0,P408/$BQ408*$BR408) -> 0 | S408: =_xlfn.IFNA(VLOOKUP(R408,Ptd_Mtr!$A:$B,2,FALSE),0) -> 0 | T408: =IF(S408=0,0,S408/$BQ408*$BR408) -> 0 | V408: =_xlfn.IFNA(VLOOKUP(U408,Ptd_Mtr!$A:$B,2,FALSE),0) -> 0 | W408: =IF(V408=0,0,V408/$BQ408*$BR408) -> 0 | Y408: =_xlfn.IFNA(VLOOKUP(X408,Ptd_Mtr!$A:$B,2,FALSE),0) -> 0 | Z408: =IF(Y408=0,0,Y408/$BQ408*$BR408) -> 0 | AB408: =_xlfn.IFNA(VLOOKUP(AA408,Ptd_Mtr!$A:$B,2,FALSE),0) -> 0 | AC408: =IF(AB408=0,0,AB408/$BQ408*$BR408) -> 0 | AE408: =_xlfn.IFNA(VLOOKUP(AD408,Ptd_Mtr!$A:$B,2,FALSE),0) -> 0 | AF408: =IF(AE408=0,0,AE408/$BQ408*$BR408) -> 0 | AH408: =_xlfn.IFNA(VLOOKUP(AG408,Ptd_Mtr!$A:$B,2,FALSE),0) -> 0 | AI408: =IF(AH408=0,0,AH408/$BQ408*$BR408) -> 0 | AK408: =_xlfn.IFNA(VLOOKUP(AJ408,Ptd_Mtr!$A:$B,2,FALSE),0) -> 0 | AL408: =IF(AK408=0,0,AK408/$BQ408*$BR408) -> 0 | AN408: =_xlfn.IFNA(VLOOKUP(AM408,Ptd_Mtr!$A:$B,2,FALSE),0) -> 0 | AO408: =IF(AN408=0,0,AN408/$BQ408*$BR408) -> 0 | AQ408: =_xlfn.IFNA(VLOOKUP(AP408,Ptd_Mtr!$A:$B,2,FALSE),0) -> 0 | AR408: =IF(AQ408=0,0,AQ408/$BQ408*$BR408) -> 0 | AT408: =_xlfn.IFNA(VLOOKUP(AS408,Ptd_Mtr!$A:$B,2,FALSE),0) -> 0 | AU408: =IF(AT408=0,0,AT408/$BQ408*$BR408) -> 0 | AW408: =_xlfn.IFNA(VLOOKUP(AV408,Ptd_Mtr!$A:$B,2,FALSE),0) -> 0 | AX408: =IF(AW408=0,0,AW408/$BQ408*$BR408) -> 0 | AZ408: =_xlfn.IFNA(VLOOKUP(AY408,Ptd_Mtr!$A:$B,2,FALSE),0) -> 0 | BA408: =IF(AZ408=0,0,AZ408/$BQ408*$BR408) -> 0 | BC408: =_xlfn.IFNA(VLOOKUP(BB408,Ptd_Mtr!$A:$B,2,FALSE),0) -> 0 | BD408: =IF(BC408=0,0,BC408/$BQ408*$BR408) -> 0 | BF408: =_xlfn.IFNA(VLOOKUP(BE408,Ptd_Mtr!$A:$B,2,FALSE),0) -> 0 | BG408: =IF(BF408=0,0,BF408/$BQ408*$BR408) -> 0 | BI408: =_xlfn.IFNA(VLOOKUP(BH408,Ptd_Mtr!$A:$B,2,FALSE),0) -> 0 | BJ408: =IF(BI408=0,0,BI408/$BQ408*$BR408) -> 0 | BL408: =_xlfn.IFNA(VLOOKUP(BK408,Ptd_Mtr!$A:$B,2,FALSE),0) -> 0 | BM408: =IF(BL408=0,0,BL408/$BQ408*$BR408) -> 0 | BO408: =_xlfn.IFNA(VLOOKUP(BN408,Ptd_Mtr!$A:$B,2,FALSE),0) -> 0 | BP408: =IF(BO408=0,0,BO408/$BQ408*$BR408) -> 0 | BQ408: =+M408+J408+P408+S408+V408+G408+Y408+AB408+AE408+AH408+AK408+AN408+AQ408+AT408+AW408+AZ408+BC408+BF408+BI408+BL408+BO408 -> 0 | BR408: =IF(F408<>"",C408,0) -> 0
D409: =IF(F409<>"",B409-BQ409,0) -> 0 | E409: =IF(F409<>"",C409-H409-K409-N409-Q409-T409-W409-Z409-AC409-AF409-AI409-AL409-AO409-AR409-AU409-AX409-BA409-BD409-BG409-BJ409-BM409-BP409,0) -> 0 | G409: =_xlfn.IFNA(VLOOKUP(F409,Ptd_Mtr!$A:$B,2,FALSE),0) -> 0 | H409: =IF(G409=0,0,G409/$BQ409*$BR409) -> 0 | J409: =_xlfn.IFNA(VLOOKUP(I409,Ptd_Mtr!$A:$B,2,FALSE),0) -> 0 | K409: =IF(J409=0,0,J409/$BQ409*$BR409) -> 0 | M409: =_xlfn.IFNA(VLOOKUP(L409,Ptd_Mtr!$A:$B,2,FALSE),0) -> 0 | N409: =IF(M409=0,0,M409/$BQ409*$BR409) -> 0 | P409: =_xlfn.IFNA(VLOOKUP(O409,Ptd_Mtr!$A:$B,2,FALSE),0) -> 0 | Q409: =IF(P409=0,0,P409/$BQ409*$BR409) -> 0 | S409: =_xlfn.IFNA(VLOOKUP(R409,Ptd_Mtr!$A:$B,2,FALSE),0) -> 0 | T409: =IF(S409=0,0,S409/$BQ409*$BR409) -> 0 | V409: =_xlfn.IFNA(VLOOKUP(U409,Ptd_Mtr!$A:$B,2,FALSE),0) -> 0 | W409: =IF(V409=0,0,V409/$BQ409*$BR409) -> 0 | Y409: =_xlfn.IFNA(VLOOKUP(X409,Ptd_Mtr!$A:$B,2,FALSE),0) -> 0 | Z409: =IF(Y409=0,0,Y409/$BQ409*$BR409) -> 0 | AB409: =_xlfn.IFNA(VLOOKUP(AA409,Ptd_Mtr!$A:$B,2,FALSE),0) -> 0 | AC409: =IF(AB409=0,0,AB409/$BQ409*$BR409) -> 0 | AE409: =_xlfn.IFNA(VLOOKUP(AD409,Ptd_Mtr!$A:$B,2,FALSE),0) -> 0 | AF409: =IF(AE409=0,0,AE409/$BQ409*$BR409) -> 0 | AH409: =_xlfn.IFNA(VLOOKUP(AG409,Ptd_Mtr!$A:$B,2,FALSE),0) -> 0 | AI409: =IF(AH409=0,0,AH409/$BQ409*$BR409) -> 0 | AK409: =_xlfn.IFNA(VLOOKUP(AJ409,Ptd_Mtr!$A:$B,2,FALSE),0) -> 0 | AL409: =IF(AK409=0,0,AK409/$BQ409*$BR409) -> 0 | AN409: =_xlfn.IFNA(VLOOKUP(AM409,Ptd_Mtr!$A:$B,2,FALSE),0) -> 0 | AO409: =IF(AN409=0,0,AN409/$BQ409*$BR409) -> 0 | AQ409: =_xlfn.IFNA(VLOOKUP(AP409,Ptd_Mtr!$A:$B,2,FALSE),0) -> 0 | AR409: =IF(AQ409=0,0,AQ409/$BQ409*$BR409) -> 0 | AT409: =_xlfn.IFNA(VLOOKUP(AS409,Ptd_Mtr!$A:$B,2,FALSE),0) -> 0 | AU409: =IF(AT409=0,0,AT409/$BQ409*$BR409) -> 0 | AW409: =_xlfn.IFNA(VLOOKUP(AV409,Ptd_Mtr!$A:$B,2,FALSE),0) -> 0 | AX409: =IF(AW409=0,0,AW409/$BQ409*$BR409) -> 0 | AZ409: =_xlfn.IFNA(VLOOKUP(AY409,Ptd_Mtr!$A:$B,2,FALSE),0) -> 0 | BA409: =IF(AZ409=0,0,AZ409/$BQ409*$BR409) -> 0 | BC409: =_xlfn.IFNA(VLOOKUP(BB409,Ptd_Mtr!$A:$B,2,FALSE),0) -> 0 | BD409: =IF(BC409=0,0,BC409/$BQ409*$BR409) -> 0 | BF409: =_xlfn.IFNA(VLOOKUP(BE409,Ptd_Mtr!$A:$B,2,FALSE),0) -> 0 | BG409: =IF(BF409=0,0,BF409/$BQ409*$BR409) -> 0 | BI409: =_xlfn.IFNA(VLOOKUP(BH409,Ptd_Mtr!$A:$B,2,FALSE),0) -> 0 | BJ409: =IF(BI409=0,0,BI409/$BQ409*$BR409) -> 0 | BL409: =_xlfn.IFNA(VLOOKUP(BK409,Ptd_Mtr!$A:$B,2,FALSE),0) -> 0 | BM409: =IF(BL409=0,0,BL409/$BQ409*$BR409) -> 0 | BO409: =_xlfn.IFNA(VLOOKUP(BN409,Ptd_Mtr!$A:$B,2,FALSE),0) -> 0 | BP409: =IF(BO409=0,0,BO409/$BQ409*$BR409) -> 0 | BQ409: =+M409+J409+P409+S409+V409+G409+Y409+AB409+AE409+AH409+AK409+AN409+AQ409+AT409+AW409+AZ409+BC409+BF409+BI409+BL409+BO409 -> 0 | BR409: =IF(F409<>"",C409,0) -> 0
D410: =IF(F410<>"",B410-BQ410,0) -> 0 | E410: =IF(F410<>"",C410-H410-K410-N410-Q410-T410-W410-Z410-AC410-AF410-AI410-AL410-AO410-AR410-AU410-AX410-BA410-BD410-BG410-BJ410-BM410-BP410,0) -> 0 | G410: =_xlfn.IFNA(VLOOKUP(F410,Ptd_Mtr!$A:$B,2,FALSE),0) -> 0 | H410: =IF(G410=0,0,G410/$BQ410*$BR410) -> 0 | J410: =_xlfn.IFNA(VLOOKUP(I410,Ptd_Mtr!$A:$B,2,FALSE),0) -> 0 | K410: =IF(J410=0,0,J410/$BQ410*$BR410) -> 0 | M410: =_xlfn.IFNA(VLOOKUP(L410,Ptd_Mtr!$A:$B,2,FALSE),0) -> 0 | N410: =IF(M410=0,0,M410/$BQ410*$BR410) -> 0 | P410: =_xlfn.IFNA(VLOOKUP(O410,Ptd_Mtr!$A:$B,2,FALSE),0) -> 0 | Q410: =IF(P410=0,0,P410/$BQ410*$BR410) -> 0 | S410: =_xlfn.IFNA(VLOOKUP(R410,Ptd_Mtr!$A:$B,2,FALSE),0) -> 0 | T410: =IF(S410=0,0,S410/$BQ410*$BR410) -> 0 | V410: =_xlfn.IFNA(VLOOKUP(U410,Ptd_Mtr!$A:$B,2,FALSE),0) -> 0 | W410: =IF(V410=0,0,V410/$BQ410*$BR410) -> 0 | Y410: =_xlfn.IFNA(VLOOKUP(X410,Ptd_Mtr!$A:$B,2,FALSE),0) -> 0 | Z410: =IF(Y410=0,0,Y410/$BQ410*$BR410) -> 0 | AB410: =_xlfn.IFNA(VLOOKUP(AA410,Ptd_Mtr!$A:$B,2,FALSE),0) -> 0 | AC410: =IF(AB410=0,0,AB410/$BQ410*$BR410) -> 0 | AE410: =_xlfn.IFNA(VLOOKUP(AD410,Ptd_Mtr!$A:$B,2,FALSE),0) -> 0 | AF410: =IF(AE410=0,0,AE410/$BQ410*$BR410) -> 0 | AH410: =_xlfn.IFNA(VLOOKUP(AG410,Ptd_Mtr!$A:$B,2,FALSE),0) -> 0 | AI410: =IF(AH410=0,0,AH410/$BQ410*$BR410) -> 0 | AK410: =_xlfn.IFNA(VLOOKUP(AJ410,Ptd_Mtr!$A:$B,2,FALSE),0) -> 0 | AL410: =IF(AK410=0,0,AK410/$BQ410*$BR410) -> 0 | AN410: =_xlfn.IFNA(VLOOKUP(AM410,Ptd_Mtr!$A:$B,2,FALSE),0) -> 0 | AO410: =IF(AN410=0,0,AN410/$BQ410*$BR410) -> 0 | AQ410: =_xlfn.IFNA(VLOOKUP(AP410,Ptd_Mtr!$A:$B,2,FALSE),0) -> 0 | AR410: =IF(AQ410=0,0,AQ410/$BQ410*$BR410) -> 0 | AT410: =_xlfn.IFNA(VLOOKUP(AS410,Ptd_Mtr!$A:$B,2,FALSE),0) -> 0 | AU410: =IF(AT410=0,0,AT410/$BQ410*$BR410) -> 0 | AW410: =_xlfn.IFNA(VLOOKUP(AV410,Ptd_Mtr!$A:$B,2,FALSE),0) -> 0 | AX410: =IF(AW410=0,0,AW410/$BQ410*$BR410) -> 0 | AZ410: =_xlfn.IFNA(VLOOKUP(AY410,Ptd_Mtr!$A:$B,2,FALSE),0) -> 0 | BA410: =IF(AZ410=0,0,AZ410/$BQ410*$BR410) -> 0 | BC410: =_xlfn.IFNA(VLOOKUP(BB410,Ptd_Mtr!$A:$B,2,FALSE),0) -> 0 | BD410: =IF(BC410=0,0,BC410/$BQ410*$BR410) -> 0 | BF410: =_xlfn.IFNA(VLOOKUP(BE410,Ptd_Mtr!$A:$B,2,FALSE),0) -> 0 | BG410: =IF(BF410=0,0,BF410/$BQ410*$BR410) -> 0 | BI410: =_xlfn.IFNA(VLOOKUP(BH410,Ptd_Mtr!$A:$B,2,FALSE),0) -> 0 | BJ410: =IF(BI410=0,0,BI410/$BQ410*$BR410) -> 0 | BL410: =_xlfn.IFNA(VLOOKUP(BK410,Ptd_Mtr!$A:$B,2,FALSE),0) -> 0 | BM410: =IF(BL410=0,0,BL410/$BQ410*$BR410) -> 0 | BO410: =_xlfn.IFNA(VLOOKUP(BN410,Ptd_Mtr!$A:$B,2,FALSE),0) -> 0 | BP410: =IF(BO410=0,0,BO410/$BQ410*$BR410) -> 0 | BQ410: =+M410+J410+P410+S410+V410+G410+Y410+AB410+AE410+AH410+AK410+AN410+AQ410+AT410+AW410+AZ410+BC410+BF410+BI410+BL410+BO410 -> 0 | BR410: =IF(F410<>"",C410,0) -> 0
D411: =IF(F411<>"",B411-BQ411,0) -> 0 | E411: =IF(F411<>"",C411-H411-K411-N411-Q411-T411-W411-Z411-AC411-AF411-AI411-AL411-AO411-AR411-AU411-AX411-BA411-BD411-BG411-BJ411-BM411-BP411,0) -> 0 | G411: =_xlfn.IFNA(VLOOKUP(F411,Ptd_Mtr!$A:$B,2,FALSE),0) -> 0 | H411: =IF(G411=0,0,G411/$BQ411*$BR411) -> 0 | J411: =_xlfn.IFNA(VLOOKUP(I411,Ptd_Mtr!$A:$B,2,FALSE),0) -> 0 | K411: =IF(J411=0,0,J411/$BQ411*$BR411) -> 0 | M411: =_xlfn.IFNA(VLOOKUP(L411,Ptd_Mtr!$A:$B,2,FALSE),0) -> 0 | N411: =IF(M411=0,0,M411/$BQ411*$BR411) -> 0 | P411: =_xlfn.IFNA(VLOOKUP(O411,Ptd_Mtr!$A:$B,2,FALSE),0) -> 0 | Q411: =IF(P411=0,0,P411/$BQ411*$BR411) -> 0 | S411: =_xlfn.IFNA(VLOOKUP(R411,Ptd_Mtr!$A:$B,2,FALSE),0) -> 0 | T411: =IF(S411=0,0,S411/$BQ411*$BR411) -> 0 | V411: =_xlfn.IFNA(VLOOKUP(U411,Ptd_Mtr!$A:$B,2,FALSE),0) -> 0 | W411: =IF(V411=0,0,V411/$BQ411*$BR411) -> 0 | Y411: =_xlfn.IFNA(VLOOKUP(X411,Ptd_Mtr!$A:$B,2,FALSE),0) -> 0 | Z411: =IF(Y411=0,0,Y411/$BQ411*$BR411) -> 0 | AB411: =_xlfn.IFNA(VLOOKUP(AA411,Ptd_Mtr!$A:$B,2,FALSE),0) -> 0 | AC411: =IF(AB411=0,0,AB411/$BQ411*$BR411) -> 0 | AE411: =_xlfn.IFNA(VLOOKUP(AD411,Ptd_Mtr!$A:$B,2,FALSE),0) -> 0 | AF411: =IF(AE411=0,0,AE411/$BQ411*$BR411) -> 0 | AH411: =_xlfn.IFNA(VLOOKUP(AG411,Ptd_Mtr!$A:$B,2,FALSE),0) -> 0 | AI411: =IF(AH411=0,0,AH411/$BQ411*$BR411) -> 0 | AK411: =_xlfn.IFNA(VLOOKUP(AJ411,Ptd_Mtr!$A:$B,2,FALSE),0) -> 0 | AL411: =IF(AK411=0,0,AK411/$BQ411*$BR411) -> 0 | AN411: =_xlfn.IFNA(VLOOKUP(AM411,Ptd_Mtr!$A:$B,2,FALSE),0) -> 0 | AO411: =IF(AN411=0,0,AN411/$BQ411*$BR411) -> 0 | AQ411: =_xlfn.IFNA(VLOOKUP(AP411,Ptd_Mtr!$A:$B,2,FALSE),0) -> 0 | AR411: =IF(AQ411=0,0,AQ411/$BQ411*$BR411) -> 0 | AT411: =_xlfn.IFNA(VLOOKUP(AS411,Ptd_Mtr!$A:$B,2,FALSE),0) -> 0 | AU411: =IF(AT411=0,0,AT411/$BQ411*$BR411) -> 0 | AW411: =_xlfn.IFNA(VLOOKUP(AV411,Ptd_Mtr!$A:$B,2,FALSE),0) -> 0 | AX411: =IF(AW411=0,0,AW411/$BQ411*$BR411) -> 0 | AZ411: =_xlfn.IFNA(VLOOKUP(AY411,Ptd_Mtr!$A:$B,2,FALSE),0) -> 0 | BA411: =IF(AZ411=0,0,AZ411/$BQ411*$BR411) -> 0 | BC411: =_xlfn.IFNA(VLOOKUP(BB411,Ptd_Mtr!$A:$B,2,FALSE),0) -> 0 | BD411: =IF(BC411=0,0,BC411/$BQ411*$BR411) -> 0 | BF411: =_xlfn.IFNA(VLOOKUP(BE411,Ptd_Mtr!$A:$B,2,FALSE),0) -> 0 | BG411: =IF(BF411=0,0,BF411/$BQ411*$BR411) -> 0 | BI411: =_xlfn.IFNA(VLOOKUP(BH411,Ptd_Mtr!$A:$B,2,FALSE),0) -> 0 | BJ411: =IF(BI411=0,0,BI411/$BQ411*$BR411) -> 0 | BL411: =_xlfn.IFNA(VLOOKUP(BK411,Ptd_Mtr!$A:$B,2,FALSE),0) -> 0 | BM411: =IF(BL411=0,0,BL411/$BQ411*$BR411) -> 0 | BO411: =_xlfn.IFNA(VLOOKUP(BN411,Ptd_Mtr!$A:$B,2,FALSE),0) -> 0 | BP411: =IF(BO411=0,0,BO411/$BQ411*$BR411) -> 0 | BQ411: =+M411+J411+P411+S411+V411+G411+Y411+AB411+AE411+AH411+AK411+AN411+AQ411+AT411+AW411+AZ411+BC411+BF411+BI411+BL411+BO411 -> 0 | BR411: =IF(F411<>"",C411,0) -> 0
... D438: =IF(F438<>"",B438-BQ438,0) -> 0 | E438: =IF(F438<>"",C438-H438-K438-N438-Q438-T438-W438-Z438-AC438-AF438-AI438-AL438-AO438-AR438-AU438-AX438-BA438-BD438-BG438-BJ438-BM438-BP438,0) -> 0 | G438: =_xlfn.IFNA(VLOOKUP(F438,Ptd_Mtr!$A:$B,2,FALSE),0) -> 0 | H438: =IF(G438=0,0,G438/$BQ438*$BR438) -> 0 | J438: =_xlfn.IFNA(VLOOKUP(I438,Ptd_Mtr!$A:$B,2,FALSE),0) -> 0 | K438: =IF(J438=0,0,J438/$BQ438*$BR438) -> 0 | M438: =_xlfn.IFNA(VLOOKUP(L438,Ptd_Mtr!$A:$B,2,FALSE),0) -> 0 | N438: =IF(M438=0,0,M438/$BQ438*$BR438) -> 0 | P438: =_xlfn.IFNA(VLOOKUP(O438,Ptd_Mtr!$A:$B,2,FALSE),0) -> 0 | Q438: =IF(P438=0,0,P438/$BQ438*$BR438) -> 0 | S438: =_xlfn.IFNA(VLOOKUP(R438,Ptd_Mtr!$A:$B,2,FALSE),0) -> 0 | T438: =IF(S438=0,0,S438/$BQ438*$BR438) -> 0 | V438: =_xlfn.IFNA(VLOOKUP(U438,Ptd_Mtr!$A:$B,2,FALSE),0) -> 0 | W438: =IF(V438=0,0,V438/$BQ438*$BR438) -> 0 | Y438: =_xlfn.IFNA(VLOOKUP(X438,Ptd_Mtr!$A:$B,2,FALSE),0) -> 0 | Z438: =IF(Y438=0,0,Y438/$BQ438*$BR438) -> 0 | AB438: =_xlfn.IFNA(VLOOKUP(AA438,Ptd_Mtr!$A:$B,2,FALSE),0) -> 0 | AC438: =IF(AB438=0,0,AB438/$BQ438*$BR438) -> 0 | AE438: =_xlfn.IFNA(VLOOKUP(AD438,Ptd_Mtr!$A:$B,2,FALSE),0) -> 0 | AF438: =IF(AE438=0,0,AE438/$BQ438*$BR438) -> 0 | AH438: =_xlfn.IFNA(VLOOKUP(AG438,Ptd_Mtr!$A:$B,2,FALSE),0) -> 0 | AI438: =IF(AH438=0,0,AH438/$BQ438*$BR438) -> 0 | AK438: =_xlfn.IFNA(VLOOKUP(AJ438,Ptd_Mtr!$A:$B,2,FALSE),0) -> 0 | AL438: =IF(AK438=0,0,AK438/$BQ438*$BR438) -> 0 | AN438: =_xlfn.IFNA(VLOOKUP(AM438,Ptd_Mtr!$A:$B,2,FALSE),0) -> 0 | AO438: =IF(AN438=0,0,AN438/$BQ438*$BR438) -> 0 | AQ438: =_xlfn.IFNA(VLOOKUP(AP438,Ptd_Mtr!$A:$B,2,FALSE),0) -> 0 | AR438: =IF(AQ438=0,0,AQ438/$BQ438*$BR438) -> 0 | AT438: =_xlfn.IFNA(VLOOKUP(AS438,Ptd_Mtr!$A:$B,2,FALSE),0) -> 0 | AU438: =IF(AT438=0,0,AT438/$BQ438*$BR438) -> 0 | AW438: =_xlfn.IFNA(VLOOKUP(AV438,Ptd_Mtr!$A:$B,2,FALSE),0) -> 0 | AX438: =IF(AW438=0,0,AW438/$BQ438*$BR438) -> 0 | AZ438: =_xlfn.IFNA(VLOOKUP(AY438,Ptd_Mtr!$A:$B,2,FALSE),0) -> 0 | BA438: =IF(AZ438=0,0,AZ438/$BQ438*$BR438) -> 0 | BC438: =_xlfn.IFNA(VLOOKUP(BB438,Ptd_Mtr!$A:$B,2,FALSE),0) -> 0 | BD438: =IF(BC438=0,0,BC438/$BQ438*$BR438) -> 0 | BF438: =_xlfn.IFNA(VLOOKUP(BE438,Ptd_Mtr!$A:$B,2,FALSE),0) -> 0 | BG438: =IF(BF438=0,0,BF438/$BQ438*$BR438) -> 0 | BI438: =_xlfn.IFNA(VLOOKUP(BH438,Ptd_Mtr!$A:$B,2,FALSE),0) -> 0 | BJ438: =IF(BI438=0,0,BI438/$BQ438*$BR438) -> 0 | BL438: =_xlfn.IFNA(VLOOKUP(BK438,Ptd_Mtr!$A:$B,2,FALSE),0) -> 0 | BM438: =IF(BL438=0,0,BL438/$BQ438*$BR438) -> 0 | BO438: =_xlfn.IFNA(VLOOKUP(BN438,Ptd_Mtr!$A:$B,2,FALSE),0) -> 0 | BP438: =IF(BO438=0,0,BO438/$BQ438*$BR438) -> 0 | BQ438: =+M438+J438+P438+S438+V438+G438+Y438+AB438+AE438+AH438+AK438+AN438+AQ438+AT438+AW438+AZ438+BC438+BF438+BI438+BL438+BO438 -> 0 | BR438: =IF(F438<>"",C438,0) -> 0
A442: Bifurcated Work Orders | B442: Mtrs | C442: Sum of Value
A443: B01031 | B443: =SUMIF(F:F,A443,G:G)+SUMIF(I:I,A443,J:J)+SUMIF(L:L,A443,M:M)+SUMIF(O:O,A443,P:P)+SUMIF(R:R,A443,S:S)+SUMIF(U:U,A443,V:V)+SUMIF(X:X,A443,Y:Y)++SUMIF(AA:AA,A443,AB:AB)++SUMIF(AD:AD,A443,AE:AE)++SUMIF(AG:AG,A443,AH:AH)++SUMIF(AJ:AJ,A443,AK:AK)++SUMIF(AM:AM,A443,AN:AN)+SUMIF(AP:AP,A443,AQ:AQ)+SUMIF(AS:AS,A443,AT:AT)+SUMIF(AV:AV,A443,AW:AW)+SUMIF(AY:AY,A443,AZ:AZ)+SUMIF(BB:BB,A443,BC:BC)+SUMIF(BE:BE,A443,BF:BF)+SUMIF(BH:BH,A443,BI:BI)+SUMIF(BK:BK,A443,BL:BL)+SUMIF(BN:BN,A443,BO:BO) -> 0 | C443: =SUMIF(F:F,A443,H:H)+SUMIF(I:I,A443,K:K)+SUMIF(L:L,A443,N:N)+SUMIF(O:O,A443,Q:Q)+SUMIF(R:R,A443,T:T)+SUMIF(U:U,A443,W:W)+SUMIF(X:X,A443,Z:Z)+SUMIF(AA:AA,A443,AC:AC)+SUMIF(AD:AD,A443,AF:AF)+SUMIF(AG:AG,A443,AI:AI)+SUMIF(AJ:AJ,A443,AL:AL)+SUMIF(AM:AM,A443,AO:AO)+SUMIF(AP:AP,A443,AR:AR)+SUMIF(AS:AS,A443,AU:AU)+SUMIF(AV:AV,A443,AX:ZX)+SUMIF(AY:AY,A443,BA:BA)+SUMIF(BB:BB,A443,BD:BD)+SUMIF(BE:BE,A443,BG:BG)+SUMIF(BH:BH,A443,BJ:BJ)+SUMIF(BK:BK,A443,BM:BM)+SUMIF(BN:BN,A443,BP:BP) -> 0
A444: B01067 | B444: =SUMIF(F:F,A444,G:G)+SUMIF(I:I,A444,J:J)+SUMIF(L:L,A444,M:M)+SUMIF(O:O,A444,P:P)+SUMIF(R:R,A444,S:S)+SUMIF(U:U,A444,V:V)+SUMIF(X:X,A444,Y:Y)++SUMIF(AA:AA,A444,AB:AB)++SUMIF(AD:AD,A444,AE:AE)++SUMIF(AG:AG,A444,AH:AH)++SUMIF(AJ:AJ,A444,AK:AK)++SUMIF(AM:AM,A444,AN:AN)+SUMIF(AP:AP,A444,AQ:AQ)+SUMIF(AS:AS,A444,AT:AT)+SUMIF(AV:AV,A444,AW:AW)+SUMIF(AY:AY,A444,AZ:AZ)+SUMIF(BB:BB,A444,BC:BC)+SUMIF(BE:BE,A444,BF:BF)+SUMIF(BH:BH,A444,BI:BI)+SUMIF(BK:BK,A444,BL:BL)+SUMIF(BN:BN,A444,BO:BO) -> 0 | C444: =SUMIF(F:F,A444,H:H)+SUMIF(I:I,A444,K:K)+SUMIF(L:L,A444,N:N)+SUMIF(O:O,A444,Q:Q)+SUMIF(R:R,A444,T:T)+SUMIF(U:U,A444,W:W)+SUMIF(X:X,A444,Z:Z)+SUMIF(AA:AA,A444,AC:AC)+SUMIF(AD:AD,A444,AF:AF)+SUMIF(AG:AG,A444,AI:AI)+SUMIF(AJ:AJ,A444,AL:AL)+SUMIF(AM:AM,A444,AO:AO)+SUMIF(AP:AP,A444,AR:AR)+SUMIF(AS:AS,A444,AU:AU)+SUMIF(AV:AV,A444,AX:ZX)+SUMIF(AY:AY,A444,BA:BA)+SUMIF(BB:BB,A444,BD:BD)+SUMIF(BE:BE,A444,BG:BG)+SUMIF(BH:BH,A444,BJ:BJ)+SUMIF(BK:BK,A444,BM:BM)+SUMIF(BN:BN,A444,BP:BP) -> 0
A445: B01071 | B445: =SUMIF(F:F,A445,G:G)+SUMIF(I:I,A445,J:J)+SUMIF(L:L,A445,M:M)+SUMIF(O:O,A445,P:P)+SUMIF(R:R,A445,S:S)+SUMIF(U:U,A445,V:V)+SUMIF(X:X,A445,Y:Y)++SUMIF(AA:AA,A445,AB:AB)++SUMIF(AD:AD,A445,AE:AE)++SUMIF(AG:AG,A445,AH:AH)++SUMIF(AJ:AJ,A445,AK:AK)++SUMIF(AM:AM,A445,AN:AN)+SUMIF(AP:AP,A445,AQ:AQ)+SUMIF(AS:AS,A445,AT:AT)+SUMIF(AV:AV,A445,AW:AW)+SUMIF(AY:AY,A445,AZ:AZ)+SUMIF(BB:BB,A445,BC:BC)+SUMIF(BE:BE,A445,BF:BF)+SUMIF(BH:BH,A445,BI:BI)+SUMIF(BK:BK,A445,BL:BL)+SUMIF(BN:BN,A445,BO:BO) -> 0 | C445: =SUMIF(F:F,A445,H:H)+SUMIF(I:I,A445,K:K)+SUMIF(L:L,A445,N:N)+SUMIF(O:O,A445,Q:Q)+SUMIF(R:R,A445,T:T)+SUMIF(U:U,A445,W:W)+SUMIF(X:X,A445,Z:Z)+SUMIF(AA:AA,A445,AC:AC)+SUMIF(AD:AD,A445,AF:AF)+SUMIF(AG:AG,A445,AI:AI)+SUMIF(AJ:AJ,A445,AL:AL)+SUMIF(AM:AM,A445,AO:AO)+SUMIF(AP:AP,A445,AR:AR)+SUMIF(AS:AS,A445,AU:AU)+SUMIF(AV:AV,A445,AX:ZX)+SUMIF(AY:AY,A445,BA:BA)+SUMIF(BB:BB,A445,BD:BD)+SUMIF(BE:BE,A445,BG:BG)+SUMIF(BH:BH,A445,BJ:BJ)+SUMIF(BK:BK,A445,BM:BM)+SUMIF(BN:BN,A445,BP:BP) -> 0
A446: B01074 | B446: =SUMIF(F:F,A446,G:G)+SUMIF(I:I,A446,J:J)+SUMIF(L:L,A446,M:M)+SUMIF(O:O,A446,P:P)+SUMIF(R:R,A446,S:S)+SUMIF(U:U,A446,V:V)+SUMIF(X:X,A446,Y:Y)++SUMIF(AA:AA,A446,AB:AB)++SUMIF(AD:AD,A446,AE:AE)++SUMIF(AG:AG,A446,AH:AH)++SUMIF(AJ:AJ,A446,AK:AK)++SUMIF(AM:AM,A446,AN:AN)+SUMIF(AP:AP,A446,AQ:AQ)+SUMIF(AS:AS,A446,AT:AT)+SUMIF(AV:AV,A446,AW:AW)+SUMIF(AY:AY,A446,AZ:AZ)+SUMIF(BB:BB,A446,BC:BC)+SUMIF(BE:BE,A446,BF:BF)+SUMIF(BH:BH,A446,BI:BI)+SUMIF(BK:BK,A446,BL:BL)+SUMIF(BN:BN,A446,BO:BO) -> 0 | C446: =SUMIF(F:F,A446,H:H)+SUMIF(I:I,A446,K:K)+SUMIF(L:L,A446,N:N)+SUMIF(O:O,A446,Q:Q)+SUMIF(R:R,A446,T:T)+SUMIF(U:U,A446,W:W)+SUMIF(X:X,A446,Z:Z)+SUMIF(AA:AA,A446,AC:AC)+SUMIF(AD:AD,A446,AF:AF)+SUMIF(AG:AG,A446,AI:AI)+SUMIF(AJ:AJ,A446,AL:AL)+SUMIF(AM:AM,A446,AO:AO)+SUMIF(AP:AP,A446,AR:AR)+SUMIF(AS:AS,A446,AU:AU)+SUMIF(AV:AV,A446,AX:ZX)+SUMIF(AY:AY,A446,BA:BA)+SUMIF(BB:BB,A446,BD:BD)+SUMIF(BE:BE,A446,BG:BG)+SUMIF(BH:BH,A446,BJ:BJ)+SUMIF(BK:BK,A446,BM:BM)+SUMIF(BN:BN,A446,BP:BP) -> 0
A447: C00979 | B447: =SUMIF(F:F,A447,G:G)+SUMIF(I:I,A447,J:J)+SUMIF(L:L,A447,M:M)+SUMIF(O:O,A447,P:P)+SUMIF(R:R,A447,S:S)+SUMIF(U:U,A447,V:V)+SUMIF(X:X,A447,Y:Y)++SUMIF(AA:AA,A447,AB:AB)++SUMIF(AD:AD,A447,AE:AE)++SUMIF(AG:AG,A447,AH:AH)++SUMIF(AJ:AJ,A447,AK:AK)++SUMIF(AM:AM,A447,AN:AN)+SUMIF(AP:AP,A447,AQ:AQ)+SUMIF(AS:AS,A447,AT:AT)+SUMIF(AV:AV,A447,AW:AW)+SUMIF(AY:AY,A447,AZ:AZ)+SUMIF(BB:BB,A447,BC:BC)+SUMIF(BE:BE,A447,BF:BF)+SUMIF(BH:BH,A447,BI:BI)+SUMIF(BK:BK,A447,BL:BL)+SUMIF(BN:BN,A447,BO:BO) -> 0 | C447: =SUMIF(F:F,A447,H:H)+SUMIF(I:I,A447,K:K)+SUMIF(L:L,A447,N:N)+SUMIF(O:O,A447,Q:Q)+SUMIF(R:R,A447,T:T)+SUMIF(U:U,A447,W:W)+SUMIF(X:X,A447,Z:Z)+SUMIF(AA:AA,A447,AC:AC)+SUMIF(AD:AD,A447,AF:AF)+SUMIF(AG:AG,A447,AI:AI)+SUMIF(AJ:AJ,A447,AL:AL)+SUMIF(AM:AM,A447,AO:AO)+SUMIF(AP:AP,A447,AR:AR)+SUMIF(AS:AS,A447,AU:AU)+SUMIF(AV:AV,A447,AX:ZX)+SUMIF(AY:AY,A447,BA:BA)+SUMIF(BB:BB,A447,BD:BD)+SUMIF(BE:BE,A447,BG:BG)+SUMIF(BH:BH,A447,BJ:BJ)+SUMIF(BK:BK,A447,BM:BM)+SUMIF(BN:BN,A447,BP:BP) -> 0
A448: C01403 | B448: =SUMIF(F:F,A448,G:G)+SUMIF(I:I,A448,J:J)+SUMIF(L:L,A448,M:M)+SUMIF(O:O,A448,P:P)+SUMIF(R:R,A448,S:S)+SUMIF(U:U,A448,V:V)+SUMIF(X:X,A448,Y:Y)++SUMIF(AA:AA,A448,AB:AB)++SUMIF(AD:AD,A448,AE:AE)++SUMIF(AG:AG,A448,AH:AH)++SUMIF(AJ:AJ,A448,AK:AK)++SUMIF(AM:AM,A448,AN:AN)+SUMIF(AP:AP,A448,AQ:AQ)+SUMIF(AS:AS,A448,AT:AT)+SUMIF(AV:AV,A448,AW:AW)+SUMIF(AY:AY,A448,AZ:AZ)+SUMIF(BB:BB,A448,BC:BC)+SUMIF(BE:BE,A448,BF:BF)+SUMIF(BH:BH,A448,BI:BI)+SUMIF(BK:BK,A448,BL:BL)+SUMIF(BN:BN,A448,BO:BO) -> 0 | C448: =SUMIF(F:F,A448,H:H)+SUMIF(I:I,A448,K:K)+SUMIF(L:L,A448,N:N)+SUMIF(O:O,A448,Q:Q)+SUMIF(R:R,A448,T:T)+SUMIF(U:U,A448,W:W)+SUMIF(X:X,A448,Z:Z)+SUMIF(AA:AA,A448,AC:AC)+SUMIF(AD:AD,A448,AF:AF)+SUMIF(AG:AG,A448,AI:AI)+SUMIF(AJ:AJ,A448,AL:AL)+SUMIF(AM:AM,A448,AO:AO)+SUMIF(AP:AP,A448,AR:AR)+SUMIF(AS:AS,A448,AU:AU)+SUMIF(AV:AV,A448,AX:ZX)+SUMIF(AY:AY,A448,BA:BA)+SUMIF(BB:BB,A448,BD:BD)+SUMIF(BE:BE,A448,BG:BG)+SUMIF(BH:BH,A448,BJ:BJ)+SUMIF(BK:BK,A448,BM:BM)+SUMIF(BN:BN,A448,BP:BP) -> 0
A449: C01411 | B449: =SUMIF(F:F,A449,G:G)+SUMIF(I:I,A449,J:J)+SUMIF(L:L,A449,M:M)+SUMIF(O:O,A449,P:P)+SUMIF(R:R,A449,S:S)+SUMIF(U:U,A449,V:V)+SUMIF(X:X,A449,Y:Y)++SUMIF(AA:AA,A449,AB:AB)++SUMIF(AD:AD,A449,AE:AE)++SUMIF(AG:AG,A449,AH:AH)++SUMIF(AJ:AJ,A449,AK:AK)++SUMIF(AM:AM,A449,AN:AN)+SUMIF(AP:AP,A449,AQ:AQ)+SUMIF(AS:AS,A449,AT:AT)+SUMIF(AV:AV,A449,AW:AW)+SUMIF(AY:AY,A449,AZ:AZ)+SUMIF(BB:BB,A449,BC:BC)+SUMIF(BE:BE,A449,BF:BF)+SUMIF(BH:BH,A449,BI:BI)+SUMIF(BK:BK,A449,BL:BL)+SUMIF(BN:BN,A449,BO:BO) -> 0 | C449: =SUMIF(F:F,A449,H:H)+SUMIF(I:I,A449,K:K)+SUMIF(L:L,A449,N:N)+SUMIF(O:O,A449,Q:Q)+SUMIF(R:R,A449,T:T)+SUMIF(U:U,A449,W:W)+SUMIF(X:X,A449,Z:Z)+SUMIF(AA:AA,A449,AC:AC)+SUMIF(AD:AD,A449,AF:AF)+SUMIF(AG:AG,A449,AI:AI)+SUMIF(AJ:AJ,A449,AL:AL)+SUMIF(AM:AM,A449,AO:AO)+SUMIF(AP:AP,A449,AR:AR)+SUMIF(AS:AS,A449,AU:AU)+SUMIF(AV:AV,A449,AX:ZX)+SUMIF(AY:AY,A449,BA:BA)+SUMIF(BB:BB,A449,BD:BD)+SUMIF(BE:BE,A449,BG:BG)+SUMIF(BH:BH,A449,BJ:BJ)+SUMIF(BK:BK,A449,BM:BM)+SUMIF(BN:BN,A449,BP:BP) -> 0
A450: C01443 | B450: =SUMIF(F:F,A450,G:G)+SUMIF(I:I,A450,J:J)+SUMIF(L:L,A450,M:M)+SUMIF(O:O,A450,P:P)+SUMIF(R:R,A450,S:S)+SUMIF(U:U,A450,V:V)+SUMIF(X:X,A450,Y:Y)++SUMIF(AA:AA,A450,AB:AB)++SUMIF(AD:AD,A450,AE:AE)++SUMIF(AG:AG,A450,AH:AH)++SUMIF(AJ:AJ,A450,AK:AK)++SUMIF(AM:AM,A450,AN:AN)+SUMIF(AP:AP,A450,AQ:AQ)+SUMIF(AS:AS,A450,AT:AT)+SUMIF(AV:AV,A450,AW:AW)+SUMIF(AY:AY,A450,AZ:AZ)+SUMIF(BB:BB,A450,BC:BC)+SUMIF(BE:BE,A450,BF:BF)+SUMIF(BH:BH,A450,BI:BI)+SUMIF(BK:BK,A450,BL:BL)+SUMIF(BN:BN,A450,BO:BO) -> 0 | C450: =SUMIF(F:F,A450,H:H)+SUMIF(I:I,A450,K:K)+SUMIF(L:L,A450,N:N)+SUMIF(O:O,A450,Q:Q)+SUMIF(R:R,A450,T:T)+SUMIF(U:U,A450,W:W)+SUMIF(X:X,A450,Z:Z)+SUMIF(AA:AA,A450,AC:AC)+SUMIF(AD:AD,A450,AF:AF)+SUMIF(AG:AG,A450,AI:AI)+SUMIF(AJ:AJ,A450,AL:AL)+SUMIF(AM:AM,A450,AO:AO)+SUMIF(AP:AP,A450,AR:AR)+SUMIF(AS:AS,A450,AU:AU)+SUMIF(AV:AV,A450,AX:ZX)+SUMIF(AY:AY,A450,BA:BA)+SUMIF(BB:BB,A450,BD:BD)+SUMIF(BE:BE,A450,BG:BG)+SUMIF(BH:BH,A450,BJ:BJ)+SUMIF(BK:BK,A450,BM:BM)+SUMIF(BN:BN,A450,BP:BP) -> 0
A451: C01465 | B451: =SUMIF(F:F,A451,G:G)+SUMIF(I:I,A451,J:J)+SUMIF(L:L,A451,M:M)+SUMIF(O:O,A451,P:P)+SUMIF(R:R,A451,S:S)+SUMIF(U:U,A451,V:V)+SUMIF(X:X,A451,Y:Y)++SUMIF(AA:AA,A451,AB:AB)++SUMIF(AD:AD,A451,AE:AE)++SUMIF(AG:AG,A451,AH:AH)++SUMIF(AJ:AJ,A451,AK:AK)++SUMIF(AM:AM,A451,AN:AN)+SUMIF(AP:AP,A451,AQ:AQ)+SUMIF(AS:AS,A451,AT:AT)+SUMIF(AV:AV,A451,AW:AW)+SUMIF(AY:AY,A451,AZ:AZ)+SUMIF(BB:BB,A451,BC:BC)+SUMIF(BE:BE,A451,BF:BF)+SUMIF(BH:BH,A451,BI:BI)+SUMIF(BK:BK,A451,BL:BL)+SUMIF(BN:BN,A451,BO:BO) -> 0 | C451: =SUMIF(F:F,A451,H:H)+SUMIF(I:I,A451,K:K)+SUMIF(L:L,A451,N:N)+SUMIF(O:O,A451,Q:Q)+SUMIF(R:R,A451,T:T)+SUMIF(U:U,A451,W:W)+SUMIF(X:X,A451,Z:Z)+SUMIF(AA:AA,A451,AC:AC)+SUMIF(AD:AD,A451,AF:AF)+SUMIF(AG:AG,A451,AI:AI)+SUMIF(AJ:AJ,A451,AL:AL)+SUMIF(AM:AM,A451,AO:AO)+SUMIF(AP:AP,A451,AR:AR)+SUMIF(AS:AS,A451,AU:AU)+SUMIF(AV:AV,A451,AX:ZX)+SUMIF(AY:AY,A451,BA:BA)+SUMIF(BB:BB,A451,BD:BD)+SUMIF(BE:BE,A451,BG:BG)+SUMIF(BH:BH,A451,BJ:BJ)+SUMIF(BK:BK,A451,BM:BM)+SUMIF(BN:BN,A451,BP:BP) -> 0
A452: C01472 | B452: =SUMIF(F:F,A452,G:G)+SUMIF(I:I,A452,J:J)+SUMIF(L:L,A452,M:M)+SUMIF(O:O,A452,P:P)+SUMIF(R:R,A452,S:S)+SUMIF(U:U,A452,V:V)+SUMIF(X:X,A452,Y:Y)++SUMIF(AA:AA,A452,AB:AB)++SUMIF(AD:AD,A452,AE:AE)++SUMIF(AG:AG,A452,AH:AH)++SUMIF(AJ:AJ,A452,AK:AK)++SUMIF(AM:AM,A452,AN:AN)+SUMIF(AP:AP,A452,AQ:AQ)+SUMIF(AS:AS,A452,AT:AT)+SUMIF(AV:AV,A452,AW:AW)+SUMIF(AY:AY,A452,AZ:AZ)+SUMIF(BB:BB,A452,BC:BC)+SUMIF(BE:BE,A452,BF:BF)+SUMIF(BH:BH,A452,BI:BI)+SUMIF(BK:BK,A452,BL:BL)+SUMIF(BN:BN,A452,BO:BO) -> 0 | C452: =SUMIF(F:F,A452,H:H)+SUMIF(I:I,A452,K:K)+SUMIF(L:L,A452,N:N)+SUMIF(O:O,A452,Q:Q)+SUMIF(R:R,A452,T:T)+SUMIF(U:U,A452,W:W)+SUMIF(X:X,A452,Z:Z)+SUMIF(AA:AA,A452,AC:AC)+SUMIF(AD:AD,A452,AF:AF)+SUMIF(AG:AG,A452,AI:AI)+SUMIF(AJ:AJ,A452,AL:AL)+SUMIF(AM:AM,A452,AO:AO)+SUMIF(AP:AP,A452,AR:AR)+SUMIF(AS:AS,A452,AU:AU)+SUMIF(AV:AV,A452,AX:ZX)+SUMIF(AY:AY,A452,BA:BA)+SUMIF(BB:BB,A452,BD:BD)+SUMIF(BE:BE,A452,BG:BG)+SUMIF(BH:BH,A452,BJ:BJ)+SUMIF(BK:BK,A452,BM:BM)+SUMIF(BN:BN,A452,BP:BP) -> 0
...

Sheet Jan-2026
LC1: Check Solvent Ratio | LD1: NC Cases | LE1: PU Cases | LF1: 1.If new ink came then always check Solvent ratio | LZ1: =LL4-99842.4700000001 -> -14941.47 | MA1: =MA4-77295.32 -> 5535.49 | ME1: =4900-4313 -> 587 | MF1: =ME1-150 -> 437 | MG1: =MF1-150-63-100-30-80-20 -> -6 | MM1: =1980-240 -> 1740
DZ2: Jan-2025 rates | LD2: 1.Ethyl - 80%,Ethanol - 20% | LE2: 1.Ethyl - 30%,NPAC - 50%,NPA - 20%
DZ3: Jan-2025 rates | LD3: 2.If supplier Flint; Ethyl - 80%,IPA - 20% | LE3: 2.If supplier Toyo Liovalue ; Ethyl - 30%,NPAC - 50%,IPA - 20%
F4: =SUM(F10:F403) -> 13565850 | M4: =+'Jan-2026 rates'!J227 -> Mixed Ink | AR4: =AT4/AS4 -> 0 | AS4: =SUBTOTAL(9,AS10:AS1048576) -> 6737.5519 | AT4: =SUBTOTAL(9,AT10:AT1048576) -> 0 | BW4: 850 | CD4: =SUBTOTAL(9,CD10:CD1048576) -> 17659.323 | CE4: =SUBTOTAL(9,CE10:CE1048576) -> 0 | DO4: =SUBTOTAL(9,DO10:DO1048576) -> 15767.594 | DP4: =SUBTOTAL(9,DP10:DP1048576) -> 0 | EZ4: =SUBTOTAL(9,EZ10:EZ1048576) -> 12436.965 | FA4: =SUBTOTAL(9,FA10:FA1048576) -> 0 | GK4: =SUBTOTAL(9,GK10:GK1048576) -> 8635.5167 | GL4: =SUBTOTAL(9,GL10:GL1048576) -> 0 | HV4: =SUBTOTAL(9,HV10:HV1048576) -> 13346.333 | HW4: =SUBTOTAL(9,HW10:HW1048576) -> 0 | JG4: =SUBTOTAL(9,JG10:JG1048576) -> 38907.315 | JH4: =SUBTOTAL(9,JH10:JH1048576) -> 0 | KR4: =SUBTOTAL(9,KR10:KR1048576) -> 47889.411 | KS4: =SUBTOTAL(9,KS10:KS1048576) -> 0 | KW4: =SUBTOTAL(9,KW10:KW1048576) -> 2499 | LI4: =SUBTOTAL(9,LI10:LI1048576) -> 0 | LJ4: =+LK4-LL4 -> -78 | LK4: =SUBTOTAL(9,LK10:LK1048576) -> 84823 | LL4: =SUBTOTAL(9,LL10:LL1048576) -> 84901 | LM4: =SUBTOTAL(9,LM10:LM1048576) -> 53545.8 | LO4: =SUBTOTAL(9,LO10:LO1048576) -> 11230.2 | LQ4: =SUBTOTAL(9,LQ10:LQ1048576) -> 0 | LS4: =SUBTOTAL(9,LS10:LS1048576) -> 14375 | LU4: =SUBTOTAL(9,LU10:LU1048576) -> 5750 | LW4: =+LL4-LU1 -> 84901 | LY4: =SUBTOTAL(9,LY10:LY1048576) -> 0 | MA4: =SUBTOTAL(9,MA10:MA1048576) -> 82830.81 | MB4: =SUBTOTAL(9,MB10:MB1048576) -> 161380.01 | MC4: Check logsheet order,for any logsheet missing
J5: Colour 1 | K5: Station Number -1 | AS5: Total Station 1 | AU5: Colour 2 | AV5: Station Number -2 | CD5: Total Station 2 | CF5: Colour 3 | CG5: Station Number -3 | DO5: Total Station 3 | DQ5: Colour 4 | DR5: Station Number -4 | EZ5: Total Station 4 | FB5: Colour 5 | FC5: Station Number -5 | GK5: Total Station 5 | GM5: Colour 6 | GN5: Station Number -6 | HV5: Total Station 6 | HX5: Colour 7 | HY5: Station Number -7 | JG5: Total Station 7 | JI5: Colour 8 | JJ5: Station Number -8 | KR5: Total Station 8 | KT5: Solvent Details | LM5: SOLVENT VALUATION DETAILS | LY5: Total Value | LZ5: Rate per KG | MA5: Fresh ink issued & mixed (excl. returns) | MB5: Mix ink consumed | MC5: Logsheet #
C6: Work Order Details | K6: Dilute Ink Details | R6: Fresh Ink Details | AP6: Supplier | AQ6: Return Ink 1 Details | AV6: Dilute Ink 2 Details | BC6: Fresh Ink Details | CA6: Supplier | CB6: Return Ink 2 Details | CG6: Dilute Ink 3 Details | CN6: Fresh Ink Details | DL6: Supplier | DM6: Return Ink 3 Details | DR6: Dilute Ink 4 Details | DY6: Fresh Ink Details | EW6: Supplier | EX6: Return Ink 4 Details | FC6: Dilute Ink Details | FJ6: Fresh Ink Details | GH6: Supplier | GI6: Return Ink 5 Details | GN6: Dilute Ink Details | GU6: Fresh Ink Details | HS6: Supplier | HT6: Return Ink 6 Details | HY6: Dilute Ink 7 Details | IF6: Fresh Ink Details | JD6: Supplier | JE6: Return Ink 7 Details | JJ6: Dilute Ink 8 Details | JQ6: Fresh Ink Details | KO6: Supplier | KP6: Return Ink 8 Details | KT6: Solvent - Station-wise Qty (Kgs) | LB6: Percentage | LG6: NET CONSUMPTION
R7: Ink Name & Code | Z7: Ink Qty in Kg | BC7: Ink Name & Code | BK7: Ink Qty in Kg | CN7: Ink Name & Code | CV7: Ink Qty in Kg | DY7: Ink Name & Code | EG7: Ink Qty in Kg | FJ7: Ink Name & Code | FR7: Ink Qty in Kg | GU7: Ink Name & Code | HC7: Ink Qty in Kg | IF7: Ink Name & Code | IN7: Ink Qty in Kg | JQ7: Ink Name & Code | JY7: Ink Qty in Kg
A8: Date | B8: Shift | C8: W.O # | D8: Job Name | E8: Job Qty | F8: Mtr | G8: M/c | H8: NCE | I8: Ink GSM | K8: Last Wo#+Colour (A) | L8: Mix Ink Colour | M8: Issued Qty -kg (A) | N8: Rate | O8: Last Wo#+Colour (B) | P8: Issued Qty -kg (B) | Q8: Rate | R8: Ink-1 Code | S8: Ink-2 Code | T8: Ink-3 Code | U8: Ink-4 Code | V8: Ink-5 Code | W8: Ink-6 Code | X8: Ink-7 Code | Y8: Ink-8 Code | Z8: Ink-1 Qty | AA8: Rate | AB8: Ink-2 Qty | AC8: Rate | AD8: Ink-3 Qty | AE8: Rate | AF8: Ink-4 Qty | AG8: Rate | AH8: Ink-5 Qty | AI8: Rate | AJ8: Ink-6 Qty | AK8: Rate | AL8: Ink-7 Qty | AM8: Rate | AN8: Ink-8 Qty | AO8: Rate | AQ8: Return Qty | AR8: Rate | AS8: Qty Consumed | AT8: Amount | AV8: Last Wo#+Colour (A) | AW8: Mix Ink Colour | AX8: Issued Qty -kg (A) | AY8: Rate | AZ8: Last Wo#+Colour (B) | BA8: Issued Qty -kg (B) | BB8: Rate | BC8: Ink-1 Code | BD8: Ink-2 Code | BE8: Ink-3 Code | BF8: Ink-4 Code | BG8: Ink-5 Code | BH8: Ink-6 Code | BI8: Ink-7 Code | BJ8: Ink-8 Code | BK8: Ink-1 Qty | BL8: Rate | BM8: Ink-2 Qty | BN8: Rate | BO8: Ink-3 Qty | BP8: Rate | BQ8: Ink-4 Qty | BR8: Rate | BS8: Ink-5 Qty | BT8: Rate | BU8: Ink-6 Qty | BV8: Rate | BW8: Ink-7 Qty | BX8: Rate | BY8: Ink-8 Qty | BZ8: Rate | CB8: Return Qty | CC8: Rate | CD8: Qty Consumed | CE8: Amount | CG8: Last Wo#+Colour (A) | CH8: Mix Ink Colour | CI8: Issued Qty -kg (A) | CJ8: Rate | CK8: Last Wo#+Colour (B) | CL8: Issued Qty -kg (B) | CM8: Rate | CN8: Ink-1 Code | CO8: Ink-2 Code | CP8: Ink-3 Code | CQ8: Ink-4 Code | CR8: Ink-5 Code | CS8: Ink-6 Code | CT8: Ink-7 Code | CU8: Ink-8 Code | CV8: Ink-1 Qty | CW8: Rate | CX8: Ink-2 Qty | CY8: Rate | CZ8: Ink-3 Qty | DA8: Rate | DB8: Ink-4 Qty | DC8: Rate | DD8: Ink-5 Qty | DE8: Rate | DF8: Ink-6 Qty | DG8: Rate | DH8: Ink-7 Qty | DI8: Rate | DJ8: Ink-8 Qty | DK8: Rate | DM8: Return Qty | DN8: Rate | DO8: Qty Consumed | DP8: Amount | DR8: Last Wo#+Colour (A) | DS8: Mix Ink Colour | DT8: Issued Qty -kg (A) | DU8: Rate | DV8: Last Wo#+Colour (B) | DW8: Issued Qty -kg (B) | DX8: Rate | DY8: Ink-1 Code | DZ8: Ink-2 Code | EA8: Ink-3 Code | EB8: Ink-4 Code | EC8: Ink-5 Code | ED8: Ink-6 Code | EE8: Ink-7 Code | EF8: Ink-8 Code | EG8: Ink-1 Qty | EH8: Rate | EI8: Ink-2 Qty | EJ8: Rate | EK8: Ink-3 Qty | EL8: Rate | EM8: Ink-4 Qty | EN8: Rate | EO8: Ink-5 Qty | EP8: Rate | EQ8: Ink-6 Qty | ER8: Rate | ES8: Ink-7 Qty | ET8: Rate | EU8: Ink-8 Qty | EV8: Rate | EX8: Return Qty | EY8: Rate | EZ8: Qty Consumed | FA8: Amount | FC8: Last Wo#+Colour (A) | FD8: Mix Ink Colour | FE8: Issued Qty -kg (A) | FF8: Rate | FG8: Last Wo#+Colour (B) | FH8: Issued Qty -kg (B) | FI8: Rate | FJ8: Ink-1 Code | FK8: Ink-2 Code | FL8: Ink-3 Code | FM8: Ink-4 Code | FN8: Ink-5 Code | FO8: Ink-6 Code | FP8: Ink-7 Code | FQ8: Ink-8 Code | FR8: Ink-1 Qty | FS8: Rate | FT8: Ink-2 Qty | FU8: Rate | FV8: Ink-3 Qty | FW8: Rate | FX8: Ink-4 Qty | FY8: Rate | FZ8: Ink-5 Qty | GA8: Rate | GB8: Ink-6 Qty | GC8: Rate | GD8: Ink-7 Qty | GE8: Rate | GF8: Ink-8 Qty | GG8: Rate | GI8: Return Qty | GJ8: Rate | GK8: Qty Consumed | GL8: Amount | GN8: Last Wo#+Colour (A) | GO8: Mix Ink Colour | GP8: Issued Qty -kg (A) | GQ8: Rate | GR8: Last Wo#+Colour (B) | GS8: Issued Qty -kg (B) | GT8: Rate | GU8: Ink-1 Code | GV8: Ink-2 Code | GW8: Ink-3 Code | GX8: Ink-4 Code | GY8: Ink-5 Code | GZ8: Ink-6 Code | HA8: Ink-7 Code | HB8: Ink-8 Code | HC8: Ink-1 Qty | HD8: Rate | HE8: Ink-2 Qty | HF8: Rate | HG8: Ink-3 Qty | HH8: Rate | HI8: Ink-4 Qty | HJ8: Rate | HK8: Ink-5 Qty | HL8: Rate | HM8: Ink-6 Qty | HN8: Rate | HO8: Ink-7 Qty | HP8: Rate | HQ8: Ink-8 Qty | HR8: Rate | HT8: Return Qty | HU8: Rate | HV8: Qty Consumed | HW8: Amount | HY8: Last Wo#+Colour (A) | HZ8: Mix Ink Colour | IA8: Issued Qty -kg (A) | IB8: Rate | IC8: Last Wo#+Colour (B) | ID8: Issued Qty -kg (B) | IE8: Rate | IF8: Ink-1 Code | IG8: Ink-2 Code | IH8: Ink-3 Code | II8: Ink-4 Code | IJ8: Ink-5 Code | IK8: Ink-6 Code | IL8: Ink-7 Code | IM8: Ink-8 Code | IN8: Ink-1 Qty | IO8: Rate | IP8: Ink-2 Qty | IQ8: Rate | IR8: Ink-3 Qty | IS8: Rate | IT8: Ink-4 Qty | IU8: Rate | IV8: Ink-5 Qty | IW8: Rate | IX8: Ink-6 Qty | IY8: Rate | IZ8: Ink-7 Qty | JA8: Rate | JB8: Ink-8 Qty | JC8: Rate | JE8: Return Qty | JF8: Rate | JG8: Qty Consumed | JH8: Amount | JJ8: Last Wo# + Colour (A) | JK8: Mix Ink Colour | JL8: Issued Qty -kg (A) | JM8: Rate | JN8: Last Wo# + Colour (B) | JO8: Issued Qty -kg (B) | JP8: Rate | JQ8: Ink-1 Code | JR8: Ink-2 Code | JS8: Ink-3 Code | JT8: Ink-4 Code | JU8: Ink-5 Code | JV8: Ink-6 Code | JW8: Ink-7 Code | JX8: Ink-8 Code | JY8: Ink-1 Qty | JZ8: Rate | KA8: Ink-2 Qty | KB8: Rate | KC8: Ink-3 Qty | KD8: Rate | KE8: Ink-4 Qty | KF8: Rate | KG8: Ink-5 Qty | KH8: Rate | KI8: Ink-6 Qty | KJ8: Rate | KK8: Ink-7 Qty | KL8: Rate | KM8: Ink-8 Qty | KN8: Rate | KP8: Return Qty | KQ8: Rate | KR8: Qty Consumed | KS8: Amount | KT8: Station1 allocated kg | KU8: Station2 allocated kg | KV8: Station3 allocated kg | KW8: Station4 allocated kg | KX8: Station5 allocated kg | KY8: Station6 allocated kg | KZ8: Station7 allocated kg | LA8: Station8 allocated kg | LB8: Ethyl % | LC8: Ethnol % | LD8: PM % (Lami) / IPA (belle) | LE8: MIBK% (Lami)/ NPAC (belle) | LF8: NPA % | LG8: Opening kg | LH8: Issued | LI8: NCE solvent | LJ8: Closing kg | LK8: Net Solvent consumed | LL8: Solvent issued (ROTO) | LM8: Ethyl Qty | LN8: Rate | LO8: Ethnol Qty | LP8: Rate | LQ8: IPA Qty | LR8: Rate | LS8: NPAC Qty | LT8: Rate | LU8: NPA Qty | LV8: Rate | LW8: Solvent Amount | LX8: Solvent Ave rate | ME8: Qty consumed at each Station (+/-) | MQ8: SOLID CONT | MR8: SOLV RTO | MT8: 1 | MU8: 1 | MV8: 2 | MW8: 2 | MX8: 3 | MY8: 3 | MZ8: 4 | NA8: 4 | NB8: 5 | NC8: 5 | ND8: 6 | NE8: 6 | NF8: 7 | NG8: 7 | NH8: 8 | NI8: 8
